Workbook

Sheet X「2023訂單資訊含入庫日」含阿爾卑斯
A1: 訂單編號 | B1: 產品代號 | C1: 產品名稱 | D1: 訂單數量 | E1: 到客戶 倉庫日 | F1: 原料齊料點 | G1: 物料齊料點 | H1: 充填量(g) | I1: 生產公斤數(kg) | J1: 需求批次 | K1: 製程設備 | L1: 預攪 | M1: 攪料 | N1: 清洗 | O1: 預攪 人數 | P1: 攪料 人數 | Q1: 清洗 人數 | R1: 前置 pcs/hr | S1: 洗瓶 pcs/hr | T1: 排瓶 pcs/hr | U1: 充填 pcs/hr | V1: 後加工 pcs/hr | W1: 前置人數 | X1: 洗瓶人數 | Y1: 排瓶人數 | Z1: 充填人數 | AA1: 後加工人數 | AB1: 入庫日 | AC1: 工單單號 | AD1: 訂單編號 | AE1: 核心碼SN
A2: 2201-22101300004-0001 | B2: MEU21D5B1P | C2: 3%傳明酸美白精華5ML | D2: 10000 | E2: 44909 | F2: 44862 | G2: 44876 | H2: 4.9 | I2: 50 | J2: 1 | K2: 精 | L2: 25 | M2: 70 | N2: 15 | O2: 1 | P2: 1 | Q2: 1 | R2: 0 | S2: 0 | T2: 1600 | U2: 1000 | V2: 0 | W2: 0 | X2: 0 | Y2: 1 | Z2: 4 | AA2: 0 | AB2: 45266
A3: 2201-23031600003-0001 | B3: MDD20D1K1N | C3: 10%杏仁酸精華100ml | D3: 70 | E3: 45051 | F3: 45027 | G3: 45001 | H3: 99.1 | I3: 7 | J3: 1 | K3: 精 | L3: 65 | M3: 65 | N3: 20 | O3: 1 | P3: 1 | Q3: 1 | R3: 0 | S3: 0 | T3: 1000 | U3: 390 | V3: 0 | W3: 0 | X3: 0 | Y3: 1 | Z3: 4 | AA3: 0 | AB3: 45051
A4: 2201-22111500001-0002 | B4: MEU21C1D2P | C4: 杜鵑花酸亮白化妝水15ML | D4: 10000 | E4: 44998 | F4: 44915 | G4: 44960 | H4: 11.7 | I4: 117 | J4: 1 | K4: 大 | L4: 70 | M4: 70 | N4: 30 | O4: 1 | P4: 1 | Q4: 1 | R4: 0 | S4: 0 | T4: 1100 | U4: 820 | V4: 0 | W4: 0 | X4: 0 | Y4: 1 | Z4: 4 | AA4: 0 | AB4: 44991
A5: 2201-22111500001-0001 | B5: MEU21C1D2P | C5: 杜鵑花酸亮白化妝水15ML | D5: 184 | E5: 44998 | F5: 44915 | G5: 44960 | H5: 11.7 | I5: 3 | J5: 1 | K5: 大 | L5: 70 | M5: 70 | N5: 30 | O5: 1 | P5: 1 | Q5: 1 | R5: 0 | S5: 0 | T5: 1100 | U5: 820 | V5: 0 | W5: 0 | X5: 0 | Y5: 1 | Z5: 4 | AA5: 0 | AB5: 44966
A6: 2201-23031700003-0001 | B6: PN1UVH7F2P | C6: 水感全效防曬乳 SPF50+/★★★★ | D6: 6000 | E6: 45058 | F6: 45027 | G6: 45002 | H6: 30 | I6: 180 | J6: 3 | K6: 精 | L6: 35 | M6: 125 | N6: 15 | O6: 1 | P6: 1 | Q6: 1 | R6: 0 | S6: 0 | T6: 0 | U6: 750 | V6: 0 | W6: 0 | X6: 0 | Y6: 0 | Z6: 4 | AA6: 0 | AB6: 45043
A7: 2201-22120900002-0012 | B7: PN1CAE2H1P | C7: 積雪草B5密集護理霜50ml | D7: 3783 | E7: 45061 | F7: 44959 | G7: 44974 | H7: 42.5 | I7: 161 | J7: 4 | K7: 小乳 | L7: 40 | M7: 140 | N7: 60 | O7: 1 | P7: 1 | Q7: 1 | R7: 0 | S7: 0 | T7: 0 | U7: 420 | V7: 0 | W7: 0 | X7: 0 | Y7: 0 | Z7: 3 | AA7: 0 | AB7: 45026
A8: 2201-23022200003-0001 | B8: MAA17Z1K2P | C8: ​天然草本精油驅蚊噴液90ML | D8: 2544 | E8: 45063 | F8: 45022 | G8: 44979 | H8: 90 | I8: 229 | J8: 1 | K8: 大 | L8: 50 | M8: 90 | N8: 30 | O8: 1 | P8: 1 | Q8: 1 | R8: 0 | S8: 0 | T8: 1 | U8: 900 | V8: 0 | W8: 0 | X8: 0 | Y8: 1 | Z8: 4 | AA8: 0 | AB8: 45040
A9: 2201-23021600002-0001 | B9: MDJ20H1F1P | C9: 馨朵拉純物理嬰兒防曬乳(SPF30 PA***) 30ml | D9: 2000 | E9: 45054 | F9: 45015 | G9: 44973 | H9: 31.45 | I9: 63 | J9: 2 | K9: 小乳 | L9: 75 | M9: 165 | N9: 90 | O9: 1 | P9: 1 | Q9: 1 | R9: 0 | S9: 0 | T9: 0 | U9: 800 | V9: 0 | W9: 0 | X9: 0 | Y9: 0 | Z9: 3 | AA9: 0 | AB9: 45030
A10: 2201-22060900003-0001 | B10: MEU22D2B1P | C10: 8%杏仁酸淨痘精華5ML | D10: 10000 | E10: 45055 | F10: 44987 | G10: 44939 | H10: 5 | I10: 50 | J10: 1 | K10: 精 | L10: 20 | M10: 80 | N10: 25 | O10: 1 | P10: 1 | Q10: 1 | R10: 0 | S10: 0 | T10: 1 | U10: 1 | V10: 0 | W10: 0 | X10: 0 | Y10: 1 | Z10: 4 | AA10: 0 | AB10: 45044
A11: 2201-22122700001-0001 | B11: MEU22A1K1P | C11: 黃金蠟菊淨白潔顏露100ml | D11: 10000 | E11: 44986 | F11: 44959 | G11: 44922 | H11: 100 | I11: 1000 | J11: 3 | K11: 大 | L11: 25 | M11: 320 | N11: 50 | O11: 1 | P11: 1 | Q11: 1 | R11: 0 | S11: 0 | T11: 460 | U11: 470 | V11: 0 | W11: 0 | X11: 0 | Y11: 1 | Z11: 3 | AA11: 0 | AB11: 44981
A12: 2201-23021700002-0001 | B12: PN1CAE1D1N | C12: 積雪草B5修護純粹凝乳 | D12: 3100 | E12: 45061 | F12: 44973 | G12: 45044 | H12: 15 | I12: 47 | J12: 1 | K12: 精 | L12: 0 | M12: 90 | N12: 15 | O12: 1 | P12: 1 | Q12: 1 | R12: 0 | S12: 0 | T12: 0 | U12: 1000 | V12: 0 | W12: 0 | X12: 0 | Y12: 0 | Z12: 4 | AA12: 0 | AB12: 45054
A13: 2201-22120900003-0012 | B13: PN1VCD3F1P | C13: 極透光亮白淡斑精華30ML | D13: 15000 | E13: 45161 | F13: 44973 | G13: 45028 | H13: 30.6 | I13: 460 | J13: 5 | K13: 精 | L13: 100 | M13: 115 | N13: 50 | O13: 1 | P13: 1 | Q13: 1 | R13: 0 | S13: 554 | T13: 1235 | U13: 800 | V13: 0 | W13: 0 | X13: 1 | Y13: 1 | Z13: 3 | AA13: 0 | AB13: 45118
... A133: 2201-23071400002-0001 | B133: MHM23D2F1P | C133: 芙木之光超能A醇煥顏精華液30ML | D133: 2000 | E133: 45166 | F133: 45142 | G133: 45155 | H133: 30.2 | I133: 61 | J133: 1 | K133: 精 | L133: 25 | M133: 110 | N133: 15 | O133: 1 | P133: 1 | Q133: 1 | R133: 0 | S133: 0 | T133: 1 | U133: 950 | V133: 0 | W133: 0 | X133: 0 | Y133: 1 | Z133: 4 | AA133: 0 | AB133: 45156

Sheet X2023訂單資訊含入庫日
A1: 訂單編號 | B1: 產品代號 | C1: 產品名稱 | D1: 訂單數量 | E1: 到客戶 倉庫日 | F1: 原料齊料點 | G1: 物料齊料點 | H1: 充填量(g) | I1: 生產公斤數(kg) | J1: 需求批次 | K1: 製程設備 | L1: 預攪 | M1: 攪料 | N1: 清洗 | O1: 預攪 人數 | P1: 攪料 人數 | Q1: 清洗 人數 | R1: 前置 pcs/hr | S1: 洗瓶 pcs/hr | T1: 排瓶 pcs/hr | U1: 充填 pcs/hr | V1: 後加工 pcs/hr | W1: 前置人數 | X1: 洗瓶人數 | Y1: 排瓶人數 | Z1: 充填人數 | AA1: 後加工人數 | AB1: 入庫日
A2: 2201-22101300004-0001 | B2: MEU21D5B1P | C2: 3%傳明酸美白精華5ML | D2: 10000 | E2: 44909 | F2: 44862 | G2: 44876 | H2: 4.9 | I2: 50 | J2: 1 | K2: 精 | L2: 25 | M2: 70 | N2: 15 | O2: 1 | P2: 1 | Q2: 1 | R2: 0 | S2: 0 | T2: 1600 | U2: 1000 | V2: 0 | W2: 0 | X2: 0 | Y2: 1 | Z2: 4 | AA2: 0 | AB2: 45266
A3: 2201-23031600003-0001 | B3: MDD20D1K1N | C3: 10%杏仁酸精華100ml | D3: 70 | E3: 45051 | F3: 45027 | G3: 45001 | H3: 99.1 | I3: 7 | J3: 1 | K3: 精 | L3: 65 | M3: 65 | N3: 20 | O3: 1 | P3: 1 | Q3: 1 | R3: 0 | S3: 0 | T3: 1000 | U3: 390 | V3: 0 | W3: 0 | X3: 0 | Y3: 1 | Z3: 4 | AA3: 0 | AB3: 45051
A4: 2201-22111500001-0002 | B4: MEU21C1D2P | C4: 杜鵑花酸亮白化妝水15ML | D4: 10000 | E4: 44998 | F4: 44915 | G4: 44960 | H4: 11.7 | I4: 117 | J4: 1 | K4: 大 | L4: 70 | M4: 70 | N4: 30 | O4: 1 | P4: 1 | Q4: 1 | R4: 0 | S4: 0 | T4: 1100 | U4: 820 | V4: 0 | W4: 0 | X4: 0 | Y4: 1 | Z4: 4 | AA4: 0 | AB4: 44991
A5: 2201-22111500001-0001 | B5: MEU21C1D2P | C5: 杜鵑花酸亮白化妝水15ML | D5: 184 | E5: 44998 | F5: 44915 | G5: 44960 | H5: 11.7 | I5: 3 | J5: 1 | K5: 大 | L5: 70 | M5: 70 | N5: 30 | O5: 1 | P5: 1 | Q5: 1 | R5: 0 | S5: 0 | T5: 1100 | U5: 820 | V5: 0 | W5: 0 | X5: 0 | Y5: 1 | Z5: 4 | AA5: 0 | AB5: 44966
A6: 2201-23031700003-0001 | B6: PN1UVH7F2P | C6: 水感全效防曬乳 SPF50+/★★★★ | D6: 6000 | E6: 45058 | F6: 45027 | G6: 45002 | H6: 30 | I6: 180 | J6: 3 | K6: 精 | L6: 35 | M6: 125 | N6: 15 | O6: 1 | P6: 1 | Q6: 1 | R6: 0 | S6: 0 | T6: 0 | U6: 750 | V6: 0 | W6: 0 | X6: 0 | Y6: 0 | Z6: 4 | AA6: 0 | AB6: 45043
A7: 2201-22120900002-0012 | B7: PN1CAE2H1P | C7: 積雪草B5密集護理霜50ml | D7: 3783 | E7: 45061 | F7: 44959 | G7: 44974 | H7: 42.5 | I7: 161 | J7: 4 | K7: 小乳 | L7: 40 | M7: 140 | N7: 60 | O7: 1 | P7: 1 | Q7: 1 | R7: 0 | S7: 0 | T7: 0 | U7: 420 | V7: 0 | W7: 0 | X7: 0 | Y7: 0 | Z7: 3 | AA7: 0 | AB7: 45026
A8: 2201-23022200003-0001 | B8: MAA17Z1K2P | C8: ​天然草本精油驅蚊噴液90ML | D8: 2544 | E8: 45063 | F8: 45022 | G8: 44979 | H8: 90 | I8: 229 | J8: 1 | K8: 大 | L8: 50 | M8: 90 | N8: 30 | O8: 1 | P8: 1 | Q8: 1 | R8: 0 | S8: 0 | T8: 1 | U8: 900 | V8: 0 | W8: 0 | X8: 0 | Y8: 1 | Z8: 4 | AA8: 0 | AB8: 45040
A9: 2201-23021600002-0001 | B9: MDJ20H1F1P | C9: 馨朵拉純物理嬰兒防曬乳(SPF30 PA***) 30ml | D9: 2000 | E9: 45054 | F9: 45015 | G9: 44973 | H9: 31.45 | I9: 63 | J9: 2 | K9: 小乳 | L9: 75 | M9: 165 | N9: 90 | O9: 1 | P9: 1 | Q9: 1 | R9: 0 | S9: 0 | T9: 0 | U9: 800 | V9: 0 | W9: 0 | X9: 0 | Y9: 0 | Z9: 3 | AA9: 0 | AB9: 45030
A10: 2201-22060900003-0001 | B10: MEU22D2B1P | C10: 8%杏仁酸淨痘精華5ML | D10: 10000 | E10: 45055 | F10: 44987 | G10: 44939 | H10: 5 | I10: 50 | J10: 1 | K10: 精 | L10: 20 | M10: 80 | N10: 25 | O10: 1 | P10: 1 | Q10: 1 | R10: 0 | S10: 0 | T10: 1 | U10: 1 | V10: 0 | W10: 0 | X10: 0 | Y10: 1 | Z10: 4 | AA10: 0 | AB10: 45044
A11: 2201-22122700001-0001 | B11: MEU22A1K1P | C11: 黃金蠟菊淨白潔顏露100ml | D11: 10000 | E11: 44986 | F11: 44959 | G11: 44922 | H11: 100 | I11: 1000 | J11: 3 | K11: 大 | L11: 25 | M11: 320 | N11: 50 | O11: 1 | P11: 1 | Q11: 1 | R11: 0 | S11: 0 | T11: 460 | U11: 470 | V11: 0 | W11: 0 | X11: 0 | Y11: 1 | Z11: 3 | AA11: 0 | AB11: 44981
A12: 2201-23021700002-0001 | B12: PN1CAE1D1N | C12: 積雪草B5修護純粹凝乳 | D12: 3100 | E12: 45061 | F12: 44973 | G12: 45044 | H12: 15 | I12: 47 | J12: 1 | K12: 精 | L12: 0 | M12: 90 | N12: 15 | O12: 1 | P12: 1 | Q12: 1 | R12: 0 | S12: 0 | T12: 0 | U12: 1000 | V12: 0 | W12: 0 | X12: 0 | Y12: 0 | Z12: 4 | AA12: 0 | AB12: 45054
A13: 2201-22120900003-0012 | B13: PN1VCD3F1P | C13: 極透光亮白淡斑精華30ML | D13: 15000 | E13: 45161 | F13: 44973 | G13: 45028 | H13: 30.6 | I13: 460 | J13: 5 | K13: 精 | L13: 100 | M13: 115 | N13: 50 | O13: 1 | P13: 1 | Q13: 1 | R13: 0 | S13: 554 | T13: 1235 | U13: 800 | V13: 0 | W13: 0 | X13: 1 | Y13: 1 | Z13: 3 | AA13: 0 | AB13: 45118
... A132: 2201-23071400002-0001 | B132: MHM23D2F1P | C132: 芙木之光超能A醇煥顏精華液30ML | D132: 2000 | E132: 45166 | F132: 45142 | G132: 45155 | H132: 30.2 | I132: 61 | J132: 1 | K132: 精 | L132: 25 | M132: 110 | N132: 15 | O132: 1 | P132: 1 | Q132: 1 | R132: 0 | S132: 0 | T132: 1 | U132: 950 | V132: 0 | W132: 0 | X132: 0 | Y132: 1 | Z132: 4 | AA132: 0 | AB132: 45156

Sheet 機器限制
A1: 製造效能（已更新） | G1: 製造效能表中的機器組合： | I1: 充填效能表中的機器組合：
A2: 機器 | B2: 台數 | C2: 別稱 | D2: 可以做的攪料程序 | E2: 可以做的製造類型 | G2: =IFERROR(__xludf.DUMMYFUNCTION("SORT(UNIQUE(FILTER(FLATTEN(ARRAYFORMULA(IFERROR(SPLIT(REGEXEXTRACT(FLATTEN(SPLIT('製造效能'!F:F, ""、"")), ""\[(.*?)\]""), ""&"")))), FLATTEN(ARRAYFORMULA(IFERROR(SPLIT(REGEXEXTRACT(FLATTEN(SPLIT('製造效能'!F:F, ""、"")), ""\[(.*?)\]""), ""&"")))) <> """"))) "),"100L升溫桶槽x1") -> 100L升溫桶槽x1 | I2: =IFERROR(__xludf.DUMMYFUNCTION("SORT(UNIQUE(FILTER(FLATTEN(ARRAYFORMULA(IFERROR(SPLIT(REGEXEXTRACT(FLATTEN(SPLIT('充填效能'!E:E, ""、"")), ""\[(.*?)\]""), ""&"")))), FLATTEN(ARRAYFORMULA(IFERROR(SPLIT(REGEXEXTRACT(FLATTEN(SPLIT('充填效能'!E:E, ""、"")), ""\[(.*?)\]""), ""&"")))) <> """"))) "),"大定量缸式充填機x1") -> 大定量缸式充填機x1
A3: 小型攪拌機 | B3: 2 | D3: =IFERROR(__xludf.DUMMYFUNCTION("TEXTJOIN("", "", TRUE, UNIQUE(FILTER('製造效能'!D:D, ISNUMBER(SEARCH(A3, '製造效能'!F:F))))) "),"小乳, 精, 大, 大乳") -> 小乳, 精, 大, 大乳 | E3: =IFERROR(__xludf.DUMMYFUNCTION("TEXTJOIN("", "", TRUE, UNIQUE(FILTER('製造效能'!K:K, ISNUMBER(SEARCH(A3, '製造效能'!F:F))))) "),"乳項, 水項") -> 乳項, 水項 | G3: =IFERROR(__xludf.DUMMYFUNCTION("""COMPUTED_VALUE"""),"100L真空乳化機x1") -> 100L真空乳化機x1 | I3: =IFERROR(__xludf.DUMMYFUNCTION("""COMPUTED_VALUE"""),"大噴印機x1") -> 大噴印機x1
A4: 大型攪拌機 | B4: 5 | D4: =IFERROR(__xludf.DUMMYFUNCTION("TEXTJOIN("", "", TRUE, UNIQUE(FILTER('製造效能'!D:D, ISNUMBER(SEARCH(A4, '製造效能'!F:F))))) "),"精, 小乳, 大, 大乳") -> 精, 小乳, 大, 大乳 | E4: =IFERROR(__xludf.DUMMYFUNCTION("TEXTJOIN("", "", TRUE, UNIQUE(FILTER('製造效能'!K:K, ISNUMBER(SEARCH(A4, '製造效能'!F:F))))) "),"水項, 乳項, 油項, 油項(中), 水項(下)") -> 水項, 乳項, 油項, 油項(中), 水項(下) | G4: =IFERROR(__xludf.DUMMYFUNCTION("""COMPUTED_VALUE"""),"400L大桶槽x1") -> 400L大桶槽x1 | I4: =IFERROR(__xludf.DUMMYFUNCTION("""COMPUTED_VALUE"""),"小噴印機x1") -> 小噴印機x1
A5: 50L真空乳化機 | B5: 1 | D5: =IFERROR(__xludf.DUMMYFUNCTION("TEXTJOIN("", "", TRUE, UNIQUE(FILTER('製造效能'!D:D, ISNUMBER(SEARCH(A5, '製造效能'!F:F))))) "),"小乳, 大乳") -> 小乳, 大乳 | E5: =IFERROR(__xludf.DUMMYFUNCTION("TEXTJOIN("", "", TRUE, UNIQUE(FILTER('製造效能'!K:K, ISNUMBER(SEARCH(A5, '製造效能'!F:F))))) "),"乳項, 油項") -> 乳項, 油項 | G5: =IFERROR(__xludf.DUMMYFUNCTION("""COMPUTED_VALUE"""),"400L大桶槽x2") -> 400L大桶槽x2 | I5: =IFERROR(__xludf.DUMMYFUNCTION("""COMPUTED_VALUE"""),"自動鎖蓋機") -> 自動鎖蓋機
A6: 100L真空乳化機 | B6: 1 | D6: =IFERROR(__xludf.DUMMYFUNCTION("TEXTJOIN("", "", TRUE, UNIQUE(FILTER('製造效能'!D:D, ISNUMBER(SEARCH(A6, '製造效能'!F:F))))) "),"大乳") -> 大乳 | E6: =IFERROR(__xludf.DUMMYFUNCTION("TEXTJOIN("", "", TRUE, UNIQUE(FILTER('製造效能'!K:K, ISNUMBER(SEARCH(A6, '製造效能'!F:F))))) "),"乳項") -> 乳項 | G6: =IFERROR(__xludf.DUMMYFUNCTION("""COMPUTED_VALUE"""),"400L大桶槽x3") -> 400L大桶槽x3 | I6: =IFERROR(__xludf.DUMMYFUNCTION("""COMPUTED_VALUE"""),"自動鎖蓋機x1") -> 自動鎖蓋機x1
A7: 100L升溫桶槽 | B7: 1 | D7: =IFERROR(__xludf.DUMMYFUNCTION("TEXTJOIN("", "", TRUE, UNIQUE(FILTER('製造效能'!D:D, ISNUMBER(SEARCH(A7, '製造效能'!F:F))))) "),"精, 小乳, 大乳") -> 精, 小乳, 大乳 | E7: =IFERROR(__xludf.DUMMYFUNCTION("TEXTJOIN("", "", TRUE, UNIQUE(FILTER('製造效能'!K:K, ISNUMBER(SEARCH(A7, '製造效能'!F:F))))) "),"水項, 醇項, 乳項") -> 水項, 醇項, 乳項 | G7: =IFERROR(__xludf.DUMMYFUNCTION("""COMPUTED_VALUE"""),"400L大桶槽x4") -> 400L大桶槽x4 | I7: =IFERROR(__xludf.DUMMYFUNCTION("""COMPUTED_VALUE"""),"自動鎖蓋機X1") -> 自動鎖蓋機X1
A8: 400L大桶槽 | B8: 4 | D8: =IFERROR(__xludf.DUMMYFUNCTION("TEXTJOIN("", "", TRUE, UNIQUE(FILTER('製造效能'!D:D, ISNUMBER(SEARCH(A8, '製造效能'!F:F))))) "),"大, 精") -> 大, 精 | E8: =IFERROR(__xludf.DUMMYFUNCTION("TEXTJOIN("", "", TRUE, UNIQUE(FILTER('製造效能'!K:K, ISNUMBER(SEARCH(A8, '製造效能'!F:F))))) "),"水項, 水項(下)") -> 水項, 水項(下) | G8: =IFERROR(__xludf.DUMMYFUNCTION("""COMPUTED_VALUE"""),"500L大桶槽x1") -> 500L大桶槽x1 | I8: =IFERROR(__xludf.DUMMYFUNCTION("""COMPUTED_VALUE"""),"夾瓶輸送帶*1") -> 夾瓶輸送帶*1
A9: 500L大桶槽 | B9: 1 | D9: =IFERROR(__xludf.DUMMYFUNCTION("TEXTJOIN("", "", TRUE, UNIQUE(FILTER('製造效能'!D:D, ISNUMBER(SEARCH(A9, '製造效能'!F:F))))) "),"大, 小乳") -> 大, 小乳 | E9: =IFERROR(__xludf.DUMMYFUNCTION("TEXTJOIN("", "", TRUE, UNIQUE(FILTER('製造效能'!K:K, ISNUMBER(SEARCH(A9, '製造效能'!F:F))))) "),"水項, 乳項") -> 水項, 乳項 | G9: =IFERROR(__xludf.DUMMYFUNCTION("""COMPUTED_VALUE"""),"50L真空乳化機") -> 50L真空乳化機 | I9: =IFERROR(__xludf.DUMMYFUNCTION("""COMPUTED_VALUE"""),"夾瓶輸送帶X1") -> 夾瓶輸送帶X1
A10: 落地型均質機 | B10: 0 | D10: =IFERROR(__xludf.DUMMYFUNCTION("TEXTJOIN("", "", TRUE, UNIQUE(FILTER('製造效能'!D:D, ISNUMBER(SEARCH(A10, '製造效能'!F:F))))) "),"大, 精, 落地") -> 大, 精, 落地 | E10: =IFERROR(__xludf.DUMMYFUNCTION("TEXTJOIN("", "", TRUE, UNIQUE(FILTER('製造效能'!K:K, ISNUMBER(SEARCH(A10, '製造效能'!F:F))))) "),"水項, 乳項") -> 水項, 乳項 | G10: =IFERROR(__xludf.DUMMYFUNCTION("""COMPUTED_VALUE"""),"50L真空乳化機x1") -> 50L真空乳化機x1 | I10: =IFERROR(__xludf.DUMMYFUNCTION("""COMPUTED_VALUE"""),"夾瓶輸送帶x1") -> 夾瓶輸送帶x1
A11: 超音波震盪機 | B11: 1 | D11: =IFERROR(__xludf.DUMMYFUNCTION("TEXTJOIN("", "", TRUE, UNIQUE(FILTER('製造效能'!D:D, ISNUMBER(SEARCH(A11, '製造效能'!F:F))))) "),"小乳, 精, 大, 大乳") -> 小乳, 精, 大, 大乳 | E11: =IFERROR(__xludf.DUMMYFUNCTION("TEXTJOIN("", "", TRUE, UNIQUE(FILTER('製造效能'!K:K, ISNUMBER(SEARCH(A11, '製造效能'!F:F))))) "),"乳項, 水項") -> 乳項, 水項 | G11: =IFERROR(__xludf.DUMMYFUNCTION("""COMPUTED_VALUE"""),"大型攪拌機*1") -> 大型攪拌機*1 | I11: =IFERROR(__xludf.DUMMYFUNCTION("""COMPUTED_VALUE"""),"夾瓶輸送帶x1噴印機x1") -> 夾瓶輸送帶x1噴印機x1
G12: =IFERROR(__xludf.DUMMYFUNCTION("""COMPUTED_VALUE"""),"大型攪拌機x1") -> 大型攪拌機x1 | I12: =IFERROR(__xludf.DUMMYFUNCTION("""COMPUTED_VALUE"""),"定量缸式充填機x1") -> 定量缸式充填機x1
G13: =IFERROR(__xludf.DUMMYFUNCTION("""COMPUTED_VALUE"""),"大型攪拌機x2") -> 大型攪拌機x2 | I13: =IFERROR(__xludf.DUMMYFUNCTION("""COMPUTED_VALUE"""),"泵浦式充填機x1") -> 泵浦式充填機x1
A14: 充填效能 | G14: =IFERROR(__xludf.DUMMYFUNCTION("""COMPUTED_VALUE"""),"大型攪拌機x2-") -> 大型攪拌機x2- | I14: =IFERROR(__xludf.DUMMYFUNCTION("""COMPUTED_VALUE"""),"泵浦式充填機x2") -> 泵浦式充填機x2
A15: 機器 | B15: 台數 | C15: 別稱 | G15: =IFERROR(__xludf.DUMMYFUNCTION("""COMPUTED_VALUE"""),"大型攪拌機x3") -> 大型攪拌機x3 | I15: =IFERROR(__xludf.DUMMYFUNCTION("""COMPUTED_VALUE"""),"面膜機x1") -> 面膜機x1
A16: 單管泵浦式充填機 | B16: 0 | G16: =IFERROR(__xludf.DUMMYFUNCTION("""COMPUTED_VALUE"""),"大型攪拌機x4") -> 大型攪拌機x4 | I16: =IFERROR(__xludf.DUMMYFUNCTION("""COMPUTED_VALUE"""),"桌上型壓蓋機x1") -> 桌上型壓蓋機x1
A17: 泵浦式充填機 | B17: 2 | G17: =IFERROR(__xludf.DUMMYFUNCTION("""COMPUTED_VALUE"""),"大型攪拌機x5") -> 大型攪拌機x5 | I17: =IFERROR(__xludf.DUMMYFUNCTION("""COMPUTED_VALUE"""),"烘箱x1") -> 烘箱x1
A18: 雙管泵浦式充填機 | B18: 0 | G18: =IFERROR(__xludf.DUMMYFUNCTION("""COMPUTED_VALUE"""),"小型攪拌機*1") -> 小型攪拌機*1 | I18: =IFERROR(__xludf.DUMMYFUNCTION("""COMPUTED_VALUE"""),"啟益噴印機") -> 啟益噴印機
A19: 圓盤式自動充填機 | B19: 0 | G19: =IFERROR(__xludf.DUMMYFUNCTION("""COMPUTED_VALUE"""),"小型攪拌機x1") -> 小型攪拌機x1 | I19: =IFERROR(__xludf.DUMMYFUNCTION("""COMPUTED_VALUE"""),"啟益噴印機x1") -> 啟益噴印機x1
A20: 大定量缸式充填機 | B20: 1 | G20: =IFERROR(__xludf.DUMMYFUNCTION("""COMPUTED_VALUE"""),"小型攪拌機x2") -> 小型攪拌機x2 | I20: =IFERROR(__xludf.DUMMYFUNCTION("""COMPUTED_VALUE"""),"單管泵浦式充填機x1") -> 單管泵浦式充填機x1
A21: 定量缸式充填機 | B21: 1 | G21: =IFERROR(__xludf.DUMMYFUNCTION("""COMPUTED_VALUE"""),"烘箱x1") -> 烘箱x1 | I21: =IFERROR(__xludf.DUMMYFUNCTION("""COMPUTED_VALUE"""),"圓盤式自動充填機x1") -> 圓盤式自動充填機x1
A22: 面膜機 | B22: 1 | G22: =IFERROR(__xludf.DUMMYFUNCTION("""COMPUTED_VALUE"""),"強力大型攪拌機x1") -> 強力大型攪拌機x1 | I22: =IFERROR(__xludf.DUMMYFUNCTION("""COMPUTED_VALUE"""),"圓盤式自動充填鎖蓋機x1") -> 圓盤式自動充填鎖蓋機x1
A23: 齒輪式充填機 | B23: 0 | G23: =IFERROR(__xludf.DUMMYFUNCTION("""COMPUTED_VALUE"""),"超音波震盪機x1") -> 超音波震盪機x1 | I23: =IFERROR(__xludf.DUMMYFUNCTION("""COMPUTED_VALUE"""),"噴印機-小x1") -> 噴印機-小x1
A24: 噴印機 | B24: 2 | G24: =IFERROR(__xludf.DUMMYFUNCTION("""COMPUTED_VALUE"""),"落地型均質機x1") -> 落地型均質機x1 | I24: =IFERROR(__xludf.DUMMYFUNCTION("""COMPUTED_VALUE"""),"噴印機*1") -> 噴印機*1
A25: 烘箱 | B25: 1 | I25: =IFERROR(__xludf.DUMMYFUNCTION("""COMPUTED_VALUE"""),"噴印機x1") -> 噴印機x1
A26: 自動鎖蓋機 | B26: 1 | I26: =IFERROR(__xludf.DUMMYFUNCTION("""COMPUTED_VALUE"""),"齒輪式充填機*1") -> 齒輪式充填機*1
I27: =IFERROR(__xludf.DUMMYFUNCTION("""COMPUTED_VALUE"""),"齒輪式充填機x1") -> 齒輪式充填機x1
I28: =IFERROR(__xludf.DUMMYFUNCTION("""COMPUTED_VALUE"""),"雙管泵浦式充填機x1") -> 雙管泵浦式充填機x1

Sheet 時間線
A1: 日期 | B1: 其他時間限制 | C1: 工序 | D1: 備註
A2: 訂單成立日期
A3: 製造 | C3: 製造－預攪 | D3: 攪料前一天 | E3: 排除多次製造
C4: 製造－攪料、清洗
A5: 充填 | B5: 物料齊料點後 | C5: 充填－組裝
C6: 充填－洗瓶
C7: 充填－排瓶 | D7: 充填前一天 | E7: 排除多次排瓶
C8: 充填－前置
C9: 充填－充填
A10: 2023半成品實際入庫日
A11: "到客戶倉庫日"

Sheet 2023訂單資訊
A1: 訂單編號 | B1: 訂單成立日期 | C1: 產品代號 | D1: 核心六碼 | E1: 產品名稱 | F1: 訂單數量 | G1: 到客戶倉庫日 | H1: 2023半成品實際入庫日 | I1: 原料齊料點 | J1: 物料齊料點 | K1: 備註 | L1: 攪料程序 | M1: 單一製造項目 | N1: 製造類型 | O1: 充填重量-水項 | P1: 充填重量-油項 | Q1: 充填重量-醇項 | R1: 充填重量-乳項 | S1: 製造工作數 | T1: 製造重量g/pcs | U1: 需求產量g | V1: 製造表定批次產量kg | W1: 製造表定批次分鐘數 | X1: 製造批次 | Y1: 製造總時分鐘數*批次 | Z1: 預攪總分鐘數 | AA1: 清洗總分鐘數 | AB1: 小型攪拌機 | AC1: 大型攪拌機 | AD1: 50L真空乳化機 | AE1: 100L真空乳化機 | AF1: 100L升溫桶槽 | AG1: 400L大桶槽 | AH1: 500L大桶槽 | AI1: 落地型均質機 | AJ1: 超音波震盪機 | AK1: 充填工作數 | AL1: 排瓶表定產能pcs/hr | AM1: 排瓶產能人數 | AN1: 排瓶時數 | AO1: 充填表定產能pcs/hr | AP1: 充填產能人數 | AQ1: 充填時數 | AR1: 充填總時數*人力
A2: 2201-22112100001-0001 | B2: =DATE(2000 + MID(A2, 6, 2), MID(A2, 8, 2), MID(A2, 10, 2)) -> 44886 | C2: MEU22E1C1P | D2: =MID(C2, 2, 6) -> EU22E1 | E2: 鳶尾花A醇緊緻精華乳10ML | F2: 10000 | G2: 44980 | H2: 44970 | I2: 44726 | J2: 44726 | L2: =IFERROR(__xludf.DUMMYFUNCTION("TEXTJOIN("", "", TRUE, UNIQUE(FILTER('製造效能'!$D$2:$D$1732, '製造效能'!$B$2:$B$1732 = D2)))"),"小乳, 大乳") -> 小乳, 大乳 | M2: =IFERROR(__xludf.DUMMYFUNCTION("INDEX(UNIQUE(FILTER('製造效能'!$D$2:$D$1732, ('製造效能'!$B$2:$B$1732 = D2) * ('製造效能'!$J$2:$J$1732 = MAXIFS('製造效能'!$J$2:$J$1732, '製造效能'!$B$2:$B$1732, D2)))), 1) "),"大乳") -> 大乳 | N2: =IFERROR(__xludf.DUMMYFUNCTION("TEXTJOIN("", "", TRUE, UNIQUE(FILTER('製造效能'!$K$2:$K$1732, '製造效能'!$B$2:$B$1732 = D2)))"),"乳項") -> 乳項 | P2: =IFERROR(__xludf.DUMMYFUNCTION("IFERROR(INDEX(FILTER('充填效能'!J$2:J$1088, '充填效能'!$A$2:$A$1088=$C2, '充填效能'!$D$2:$D$1088=""充填""), 1), 0)"),"") | Q2: =IFERROR(__xludf.DUMMYFUNCTION("IFERROR(INDEX(FILTER('充填效能'!K$2:K$1088, '充填效能'!$A$2:$A$1088=$C2, '充填效能'!$D$2:$D$1088=""充填""), 1), 0)"),"") | R2: =IFERROR(__xludf.DUMMYFUNCTION("IFERROR(INDEX(FILTER('充填效能'!I$2:I$1088, '充填效能'!$A$2:$A$1088=$C2, '充填效能'!$D$2:$D$1088=""充填""), 1), 0)"),10.1) -> 10.1 | S2: =COUNTIFS(製造效能!B:B, $D2,製造效能!D:D,M2) -> 3 | T2: =IFERROR(__xludf.DUMMYFUNCTION("VALUE(REGEXEXTRACT(TO_TEXT(R2), ""\d*\.?\d+""))"),10.1) -> 10.1 | U2: =F2*T2*1.015 -> 102515 | V2: =IFERROR(__xludf.DUMMYFUNCTION("IFERROR(INDEX(FILTER('製造效能'!J:J, '製造效能'!A:A=$C2, '製造效能'!D:D=M2, '製造效能'!E:E=""攪料""), 1), INDEX(FILTER('製造效能'!J:J, '製造效能'!B:B=$D2, '製造效能'!D:D=M2, '製造效能'!E:E=""攪料""), 1))"),103) -> 103 | W2: =IFERROR(__xludf.DUMMYFUNCTION("IFERROR(INDEX(FILTER('製造效能'!G:G, '製造效能'!A:A=$C2, '製造效能'!D:D=M2, '製造效能'!E:E=""攪料""), 1), INDEX(FILTER('製造效能'!G:G, '製造效能'!B:B=$D2, '製造效能'!D:D=M2, '製造效能'!E:E=""攪料""), 1))"),200) -> 200 | X2: =ROUNDUP(U2/1000/V2,0) -> 1 | Y2: =W2*X2 -> 200 | Z2: =IFERROR(__xludf.DUMMYFUNCTION("IFERROR(IFERROR(INDEX(FILTER('製造效能'!G:G, '製造效能'!A:A=$C2, '製造效能'!D:D=M2, '製造效能'!E:E=""預攪""), 1), INDEX(FILTER('製造效能'!G:G, '製造效能'!B:B=$D2, '製造效能'!D:D=M2, '製造效能'!E:E=""預攪""), 1)), 0)"),135) -> 135 | AA2: =IFERROR(__xludf.DUMMYFUNCTION("IFERROR(INDEX(FILTER('製造效能'!G:G, '製造效能'!A:A=$C2, '製造效能'!D:D=M2, '製造效能'!E:E=""清洗""), 1), INDEX(FILTER('製造效能'!G:G, '製造效能'!B:B=$D2, '製造效能'!D:D=M2, '製造效能'!E:E=""清洗""), 1))"),40) -> 40 | AB2: =IFERROR(__xludf.DUMMYFUNCTION("IFERROR(INDEX(FILTER('製造效能'!N:N, '製造效能'!$A:$A=$C2, '製造效能'!$D:$D=$M2, '製造效能'!$E:$E=""攪料""), 1), INDEX(FILTER('製造效能'!N:N, '製造效能'!$B:$B=$D2, '製造效能'!$D:$D=$M2, '製造效能'!$E:$E=""攪料""), 1))"),"") | AC2: =IFERROR(__xludf.DUMMYFUNCTION("IFERROR(INDEX(FILTER('製造效能'!O:O, '製造效能'!$A:$A=$C2, '製造效能'!$D:$D=$M2, '製造效能'!$E:$E=""攪料""), 1), INDEX(FILTER('製造效能'!O:O, '製造效能'!$B:$B=$D2, '製造效能'!$D:$D=$M2, '製造效能'!$E:$E=""攪料""), 1))"),1) -> 1 | AD2: =IFERROR(__xludf.DUMMYFUNCTION("IFERROR(INDEX(FILTER('製造效能'!P:P, '製造效能'!$A:$A=$C2, '製造效能'!$D:$D=$M2, '製造效能'!$E:$E=""攪料""), 1), INDEX(FILTER('製造效能'!P:P, '製造效能'!$B:$B=$D2, '製造效能'!$D:$D=$M2, '製造效能'!$E:$E=""攪料""), 1))"),"") | AE2: =IFERROR(__xludf.DUMMYFUNCTION("IFERROR(INDEX(FILTER('製造效能'!Q:Q, '製造效能'!$A:$A=$C2, '製造效能'!$D:$D=$M2, '製造效能'!$E:$E=""攪料""), 1), INDEX(FILTER('製造效能'!Q:Q, '製造效能'!$B:$B=$D2, '製造效能'!$D:$D=$M2, '製造效能'!$E:$E=""攪料""), 1))"),1) -> 1 | AF2: =IFERROR(__xludf.DUMMYFUNCTION("IFERROR(INDEX(FILTER('製造效能'!R:R, '製造效能'!$A:$A=$C2, '製造效能'!$D:$D=$M2, '製造效能'!$E:$E=""攪料""), 1), INDEX(FILTER('製造效能'!R:R, '製造效能'!$B:$B=$D2, '製造效能'!$D:$D=$M2, '製造效能'!$E:$E=""攪料""), 1))"),"") | AG2: =IFERROR(__xludf.DUMMYFUNCTION("IFERROR(INDEX(FILTER('製造效能'!S:S, '製造效能'!$A:$A=$C2, '製造效能'!$D:$D=$M2, '製造效能'!$E:$E=""攪料""), 1), INDEX(FILTER('製造效能'!S:S, '製造效能'!$B:$B=$D2, '製造效能'!$D:$D=$M2, '製造效能'!$E:$E=""攪料""), 1))"),"") | AH2: =IFERROR(__xludf.DUMMYFUNCTION("IFERROR(INDEX(FILTER('製造效能'!T:T, '製造效能'!$A:$A=$C2, '製造效能'!$D:$D=$M2, '製造效能'!$E:$E=""攪料""), 1), INDEX(FILTER('製造效能'!T:T, '製造效能'!$B:$B=$D2, '製造效能'!$D:$D=$M2, '製造效能'!$E:$E=""攪料""), 1))"),"") | AI2: =IFERROR(__xludf.DUMMYFUNCTION("IFERROR(INDEX(FILTER('製造效能'!U:U, '製造效能'!$A:$A=$C2, '製造效能'!$D:$D=$M2, '製造效能'!$E:$E=""攪料""), 1), INDEX(FILTER('製造效能'!U:U, '製造效能'!$B:$B=$D2, '製造效能'!$D:$D=$M2, '製造效能'!$E:$E=""攪料""), 1))"),"") | AJ2: =IFERROR(__xludf.DUMMYFUNCTION("IFERROR(INDEX(FILTER('製造效能'!V:V, '製造效能'!$A:$A=$C2, '製造效能'!$D:$D=$M2, '製造效能'!$E:$E=""攪料""), 1), INDEX(FILTER('製造效能'!V:V, '製造效能'!$B:$B=$D2, '製造效能'!$D:$D=$M2, '製造效能'!$E:$E=""攪料""), 1))"),"") | AK2: =COUNTIF(充填效能!$A:$A, $C2) -> 1 | AL2: =IFERROR(__xludf.DUMMYFUNCTION("IFERROR(INDEX(FILTER('充填效能'!$Q$2:$Q$1088, '充填效能'!$A$2:$A$1088=$C2, '充填效能'!$D$2:$D$1088=""排瓶""), 1), 0)"),0) -> 0 | AM2: =IFERROR(__xludf.DUMMYFUNCTION("IFERROR(INDEX(FILTER('充填效能'!$R$2:$R$1088, '充填效能'!$A$2:$A$1088=$C2, '充填效能'!$D$2:$D$1088=""排瓶""), 1), 0)"),0) -> 0 | AN2: =IF(AL2=0, 0, $F2/AL2) -> 0 | AO2: =IFERROR(__xludf.DUMMYFUNCTION("IFERROR(INDEX(FILTER('充填效能'!$Q$2:$Q$1088, '充填效能'!$A$2:$A$1088=$C2, '充填效能'!$D$2:$D$1088=""充填""), 1), 0)"),"1000") -> 1000 | AP2: =IFERROR(__xludf.DUMMYFUNCTION("IFERROR(INDEX(FILTER('充填效能'!$R$2:$R$1088, '充填效能'!$A$2:$A$1088=$C2, '充填效能'!$D$2:$D$1088=""充填""), 1), 0)"),4) -> 4 | AQ2: =IF(AO2=0, 0, $F2/AO2) -> 10 | AR2: =AP2*AQ2 -> 40
A3: 2201-22061400001-0001 | B3: =DATE(2000 + MID(A3, 6, 2), MID(A3, 8, 2), MID(A3, 10, 2)) -> 44726 | C3: MAW21E1F1P | D3: =MID(C3, 2, 6) -> AW21E1 | E3: 極致水潤光保濕乳霜30ml | F3: 1700 | G3: 44974 | H3: 44971 | I3: 44957 | J3: 44886 | L3: =IFERROR(__xludf.DUMMYFUNCTION("TEXTJOIN("", "", TRUE, UNIQUE(FILTER('製造效能'!$D$2:$D$1732, '製造效能'!$B$2:$B$1732 = D3)))"),"小乳, 大乳") -> 小乳, 大乳 | M3: =IFERROR(__xludf.DUMMYFUNCTION("INDEX(UNIQUE(FILTER('製造效能'!$D$2:$D$1732, ('製造效能'!$B$2:$B$1732 = D3) * ('製造效能'!$J$2:$J$1732 = MAXIFS('製造效能'!$J$2:$J$1732, '製造效能'!$B$2:$B$1732, D3)))), 1) "),"大乳") -> 大乳 | N3: =IFERROR(__xludf.DUMMYFUNCTION("TEXTJOIN("", "", TRUE, UNIQUE(FILTER('製造效能'!$K$2:$K$1732, '製造效能'!$B$2:$B$1732 = D3)))"),"乳項") -> 乳項 | P3: =IFERROR(__xludf.DUMMYFUNCTION("IFERROR(INDEX(FILTER('充填效能'!J$2:J$1088, '充填效能'!$A$2:$A$1088=$C3, '充填效能'!$D$2:$D$1088=""充填""), 1), 0)"),"") | Q3: =IFERROR(__xludf.DUMMYFUNCTION("IFERROR(INDEX(FILTER('充填效能'!K$2:K$1088, '充填效能'!$A$2:$A$1088=$C3, '充填效能'!$D$2:$D$1088=""充填""), 1), 0)"),"") | R3: =IFERROR(__xludf.DUMMYFUNCTION("IFERROR(INDEX(FILTER('充填效能'!I$2:I$1088, '充填效能'!$A$2:$A$1088=$C3, '充填效能'!$D$2:$D$1088=""充填""), 1), 0)"),30) -> 30 | S3: =COUNTIFS(製造效能!B:B, $D3,製造效能!D:D,M3) -> 3 | T3: =IFERROR(__xludf.DUMMYFUNCTION("VALUE(REGEXEXTRACT(TO_TEXT(R3), ""\d*\.?\d+""))"),30) -> 30 | U3: =F3*T3*1.015 -> 51765 | V3: =IFERROR(__xludf.DUMMYFUNCTION("IFERROR(INDEX(FILTER('製造效能'!J:J, '製造效能'!A:A=$C3, '製造效能'!D:D=M3, '製造效能'!E:E=""攪料""), 1), INDEX(FILTER('製造效能'!J:J, '製造效能'!B:B=$D3, '製造效能'!D:D=M3, '製造效能'!E:E=""攪料""), 1))"),103) -> 103 | W3: =IFERROR(__xludf.DUMMYFUNCTION("IFERROR(INDEX(FILTER('製造效能'!G:G, '製造效能'!A:A=$C3, '製造效能'!D:D=M3, '製造效能'!E:E=""攪料""), 1), INDEX(FILTER('製造效能'!G:G, '製造效能'!B:B=$D3, '製造效能'!D:D=M3, '製造效能'!E:E=""攪料""), 1))"),180) -> 180 | X3: =ROUNDUP(U3/1000/V3,0) -> 1 | Y3: =W3*X3 -> 180 | Z3: =IFERROR(__xludf.DUMMYFUNCTION("IFERROR(IFERROR(INDEX(FILTER('製造效能'!G:G, '製造效能'!A:A=$C3, '製造效能'!D:D=M3, '製造效能'!E:E=""預攪""), 1), INDEX(FILTER('製造效能'!G:G, '製造效能'!B:B=$D3, '製造效能'!D:D=M3, '製造效能'!E:E=""預攪""), 1)), 0)"),45) -> 45 | AA3: =IFERROR(__xludf.DUMMYFUNCTION("IFERROR(INDEX(FILTER('製造效能'!G:G, '製造效能'!A:A=$C3, '製造效能'!D:D=M3, '製造效能'!E:E=""清洗""), 1), INDEX(FILTER('製造效能'!G:G, '製造效能'!B:B=$D3, '製造效能'!D:D=M3, '製造效能'!E:E=""清洗""), 1))"),40) -> 40 | AB3: =IFERROR(__xludf.DUMMYFUNCTION("IFERROR(INDEX(FILTER('製造效能'!N:N, '製造效能'!$A:$A=$C3, '製造效能'!$D:$D=$M3, '製造效能'!$E:$E=""攪料""), 1), INDEX(FILTER('製造效能'!N:N, '製造效能'!$B:$B=$D3, '製造效能'!$D:$D=$M3, '製造效能'!$E:$E=""攪料""), 1))"),"") | AC3: =IFERROR(__xludf.DUMMYFUNCTION("IFERROR(INDEX(FILTER('製造效能'!O:O, '製造效能'!$A:$A=$C3, '製造效能'!$D:$D=$M3, '製造效能'!$E:$E=""攪料""), 1), INDEX(FILTER('製造效能'!O:O, '製造效能'!$B:$B=$D3, '製造效能'!$D:$D=$M3, '製造效能'!$E:$E=""攪料""), 1))"),"") | AD3: =IFERROR(__xludf.DUMMYFUNCTION("IFERROR(INDEX(FILTER('製造效能'!P:P, '製造效能'!$A:$A=$C3, '製造效能'!$D:$D=$M3, '製造效能'!$E:$E=""攪料""), 1), INDEX(FILTER('製造效能'!P:P, '製造效能'!$B:$B=$D3, '製造效能'!$D:$D=$M3, '製造效能'!$E:$E=""攪料""), 1))"),"") | AE3: =IFERROR(__xludf.DUMMYFUNCTION("IFERROR(INDEX(FILTER('製造效能'!Q:Q, '製造效能'!$A:$A=$C3, '製造效能'!$D:$D=$M3, '製造效能'!$E:$E=""攪料""), 1), INDEX(FILTER('製造效能'!Q:Q, '製造效能'!$B:$B=$D3, '製造效能'!$D:$D=$M3, '製造效能'!$E:$E=""攪料""), 1))"),1) -> 1 | AF3: =IFERROR(__xludf.DUMMYFUNCTION("IFERROR(INDEX(FILTER('製造效能'!R:R, '製造效能'!$A:$A=$C3, '製造效能'!$D:$D=$M3, '製造效能'!$E:$E=""攪料""), 1), INDEX(FILTER('製造效能'!R:R, '製造效能'!$B:$B=$D3, '製造效能'!$D:$D=$M3, '製造效能'!$E:$E=""攪料""), 1))"),"") | AG3: =IFERROR(__xludf.DUMMYFUNCTION("IFERROR(INDEX(FILTER('製造效能'!S:S, '製造效能'!$A:$A=$C3, '製造效能'!$D:$D=$M3, '製造效能'!$E:$E=""攪料""), 1), INDEX(FILTER('製造效能'!S:S, '製造效能'!$B:$B=$D3, '製造效能'!$D:$D=$M3, '製造效能'!$E:$E=""攪料""), 1))"),"") | AH3: =IFERROR(__xludf.DUMMYFUNCTION("IFERROR(INDEX(FILTER('製造效能'!T:T, '製造效能'!$A:$A=$C3, '製造效能'!$D:$D=$M3, '製造效能'!$E:$E=""攪料""), 1), INDEX(FILTER('製造效能'!T:T, '製造效能'!$B:$B=$D3, '製造效能'!$D:$D=$M3, '製造效能'!$E:$E=""攪料""), 1))"),"") | AI3: =IFERROR(__xludf.DUMMYFUNCTION("IFERROR(INDEX(FILTER('製造效能'!U:U, '製造效能'!$A:$A=$C3, '製造效能'!$D:$D=$M3, '製造效能'!$E:$E=""攪料""), 1), INDEX(FILTER('製造效能'!U:U, '製造效能'!$B:$B=$D3, '製造效能'!$D:$D=$M3, '製造效能'!$E:$E=""攪料""), 1))"),"") | AJ3: =IFERROR(__xludf.DUMMYFUNCTION("IFERROR(INDEX(FILTER('製造效能'!V:V, '製造效能'!$A:$A=$C3, '製造效能'!$D:$D=$M3, '製造效能'!$E:$E=""攪料""), 1), INDEX(FILTER('製造效能'!V:V, '製造效能'!$B:$B=$D3, '製造效能'!$D:$D=$M3, '製造效能'!$E:$E=""攪料""), 1))"),"") | AK3: =COUNTIF(充填效能!$A:$A, $C3) -> 2 | AL3: =IFERROR(__xludf.DUMMYFUNCTION("IFERROR(INDEX(FILTER('充填效能'!$Q$2:$Q$1088, '充填效能'!$A$2:$A$1088=$C3, '充填效能'!$D$2:$D$1088=""排瓶""), 1), 0)"),"750") -> 750 | AM3: =IFERROR(__xludf.DUMMYFUNCTION("IFERROR(INDEX(FILTER('充填效能'!$R$2:$R$1088, '充填效能'!$A$2:$A$1088=$C3, '充填效能'!$D$2:$D$1088=""排瓶""), 1), 0)"),1) -> 1 | AN3: =IF(AL3=0, 0, $F3/AL3) -> 2.2666667 | AO3: =IFERROR(__xludf.DUMMYFUNCTION("IFERROR(INDEX(FILTER('充填效能'!$Q$2:$Q$1088, '充填效能'!$A$2:$A$1088=$C3, '充填效能'!$D$2:$D$1088=""充填""), 1), 0)"),"770") -> 770 | AP3: =IFERROR(__xludf.DUMMYFUNCTION("IFERROR(INDEX(FILTER('充填效能'!$R$2:$R$1088, '充填效能'!$A$2:$A$1088=$C3, '充填效能'!$D$2:$D$1088=""充填""), 1), 0)"),4) -> 4 | AQ3: =IF(AO3=0, 0, $F3/AO3) -> 2.2077922 | AR3: =AP3*AQ3 -> 8.8311688
A4: 2201-22122700001-0001 | B4: =DATE(2000 + MID(A4, 6, 2), MID(A4, 8, 2), MID(A4, 10, 2)) -> 44922 | C4: MEU22A1K1P | D4: =MID(C4, 2, 6) -> EU22A1 | E4: 黃金蠟菊淨白潔顏露100ml | F4: 10000 | G4: 44986 | H4: 44981 | I4: 44959 | J4: 44922 | L4: =IFERROR(__xludf.DUMMYFUNCTION("TEXTJOIN("", "", TRUE, UNIQUE(FILTER('製造效能'!$D$2:$D$1732, '製造效能'!$B$2:$B$1732 = D4)))"),"大") -> 大 | M4: =IFERROR(__xludf.DUMMYFUNCTION("INDEX(UNIQUE(FILTER('製造效能'!$D$2:$D$1732, ('製造效能'!$B$2:$B$1732 = D4) * ('製造效能'!$J$2:$J$1732 = MAXIFS('製造效能'!$J$2:$J$1732, '製造效能'!$B$2:$B$1732, D4)))), 1) "),"大") -> 大 | N4: =IFERROR(__xludf.DUMMYFUNCTION("TEXTJOIN("", "", TRUE, UNIQUE(FILTER('製造效能'!$K$2:$K$1732, '製造效能'!$B$2:$B$1732 = D4)))"),"水項") -> 水項 | O4: =IFERROR(__xludf.DUMMYFUNCTION("IFERROR(INDEX(FILTER('充填效能'!I$2:I$1088, '充填效能'!$A$2:$A$1088=$C4, '充填效能'!$D$2:$D$1088=""充填""), 1), 0)"),100) -> 100 | P4: =IFERROR(__xludf.DUMMYFUNCTION("IFERROR(INDEX(FILTER('充填效能'!J$2:J$1088, '充填效能'!$A$2:$A$1088=$C4, '充填效能'!$D$2:$D$1088=""充填""), 1), 0)"),"") | Q4: =IFERROR(__xludf.DUMMYFUNCTION("IFERROR(INDEX(FILTER('充填效能'!K$2:K$1088, '充填效能'!$A$2:$A$1088=$C4, '充填效能'!$D$2:$D$1088=""充填""), 1), 0)"),"") | R4: =IFERROR(__xludf.DUMMYFUNCTION("IFERROR(INDEX(FILTER('充填效能'!L$2:L$1088, '充填效能'!$A$2:$A$1088=$C4, '充填效能'!$D$2:$D$1088=""充填""), 1), 0)"),"") | S4: =COUNTIFS(製造效能!B:B, $D4,製造效能!D:D,M4) -> 3 | T4: =IFERROR(__xludf.DUMMYFUNCTION("VALUE(REGEXEXTRACT(TO_TEXT(O4), ""\d*\.?\d+""))"),100) -> 100 | U4: =F4*T4*1.015 -> 1015000 | V4: =IFERROR(__xludf.DUMMYFUNCTION("IFERROR(INDEX(FILTER('製造效能'!J:J, '製造效能'!A:A=$C4, '製造效能'!D:D=M4, '製造效能'!E:E=""攪料""), 1), INDEX(FILTER('製造效能'!J:J, '製造效能'!B:B=$D4, '製造效能'!D:D=M4, '製造效能'!E:E=""攪料""), 1))"),367.5) -> 367.5 | W4: =IFERROR(__xludf.DUMMYFUNCTION("IFERROR(INDEX(FILTER('製造效能'!G:G, '製造效能'!A:A=$C4, '製造效能'!D:D=M4, '製造效能'!E:E=""攪料""), 1), INDEX(FILTER('製造效能'!G:G, '製造效能'!B:B=$D4, '製造效能'!D:D=M4, '製造效能'!E:E=""攪料""), 1))"),320) -> 320 | X4: =ROUNDUP(U4/1000/V4,0) -> 3 | Y4: =W4*X4 -> 960 | Z4: =IFERROR(__xludf.DUMMYFUNCTION("IFERROR(IFERROR(INDEX(FILTER('製造效能'!G:G, '製造效能'!A:A=$C4, '製造效能'!D:D=M4, '製造效能'!E:E=""預攪""), 1), INDEX(FILTER('製造效能'!G:G, '製造效能'!B:B=$D4, '製造效能'!D:D=M4, '製造效能'!E:E=""預攪""), 1)), 0)"),25) -> 25 | AA4: =IFERROR(__xludf.DUMMYFUNCTION("IFERROR(INDEX(FILTER('製造效能'!G:G, '製造效能'!A:A=$C4, '製造效能'!D:D=M4, '製造效能'!E:E=""清洗""), 1), INDEX(FILTER('製造效能'!G:G, '製造效能'!B:B=$D4, '製造效能'!D:D=M4, '製造效能'!E:E=""清洗""), 1))"),50) -> 50 | AB4: =IFERROR(__xludf.DUMMYFUNCTION("IFERROR(INDEX(FILTER('製造效能'!N:N, '製造效能'!$A:$A=$C4, '製造效能'!$D:$D=$M4, '製造效能'!$E:$E=""攪料""), 1), INDEX(FILTER('製造效能'!N:N, '製造效能'!$B:$B=$D4, '製造效能'!$D:$D=$M4, '製造效能'!$E:$E=""攪料""), 1))"),"") | AC4: =IFERROR(__xludf.DUMMYFUNCTION("IFERROR(INDEX(FILTER('製造效能'!O:O, '製造效能'!$A:$A=$C4, '製造效能'!$D:$D=$M4, '製造效能'!$E:$E=""攪料""), 1), INDEX(FILTER('製造效能'!O:O, '製造效能'!$B:$B=$D4, '製造效能'!$D:$D=$M4, '製造效能'!$E:$E=""攪料""), 1))"),"") | AD4: =IFERROR(__xludf.DUMMYFUNCTION("IFERROR(INDEX(FILTER('製造效能'!P:P, '製造效能'!$A:$A=$C4, '製造效能'!$D:$D=$M4, '製造效能'!$E:$E=""攪料""), 1), INDEX(FILTER('製造效能'!P:P, '製造效能'!$B:$B=$D4, '製造效能'!$D:$D=$M4, '製造效能'!$E:$E=""攪料""), 1))"),"") | AE4: =IFERROR(__xludf.DUMMYFUNCTION("IFERROR(INDEX(FILTER('製造效能'!Q:Q, '製造效能'!$A:$A=$C4, '製造效能'!$D:$D=$M4, '製造效能'!$E:$E=""攪料""), 1), INDEX(FILTER('製造效能'!Q:Q, '製造效能'!$B:$B=$D4, '製造效能'!$D:$D=$M4, '製造效能'!$E:$E=""攪料""), 1))"),"") | AF4: =IFERROR(__xludf.DUMMYFUNCTION("IFERROR(INDEX(FILTER('製造效能'!R:R, '製造效能'!$A:$A=$C4, '製造效能'!$D:$D=$M4, '製造效能'!$E:$E=""攪料""), 1), INDEX(FILTER('製造效能'!R:R, '製造效能'!$B:$B=$D4, '製造效能'!$D:$D=$M4, '製造效能'!$E:$E=""攪料""), 1))"),"") | AG4: =IFERROR(__xludf.DUMMYFUNCTION("IFERROR(INDEX(FILTER('製造效能'!S:S, '製造效能'!$A:$A=$C4, '製造效能'!$D:$D=$M4, '製造效能'!$E:$E=""攪料""), 1), INDEX(FILTER('製造效能'!S:S, '製造效能'!$B:$B=$D4, '製造效能'!$D:$D=$M4, '製造效能'!$E:$E=""攪料""), 1))"),1) -> 1 | AH4: =IFERROR(__xludf.DUMMYFUNCTION("IFERROR(INDEX(FILTER('製造效能'!T:T, '製造效能'!$A:$A=$C4, '製造效能'!$D:$D=$M4, '製造效能'!$E:$E=""攪料""), 1), INDEX(FILTER('製造效能'!T:T, '製造效能'!$B:$B=$D4, '製造效能'!$D:$D=$M4, '製造效能'!$E:$E=""攪料""), 1))"),"") | AI4: =IFERROR(__xludf.DUMMYFUNCTION("IFERROR(INDEX(FILTER('製造效能'!U:U, '製造效能'!$A:$A=$C4, '製造效能'!$D:$D=$M4, '製造效能'!$E:$E=""攪料""), 1), INDEX(FILTER('製造效能'!U:U, '製造效能'!$B:$B=$D4, '製造效能'!$D:$D=$M4, '製造效能'!$E:$E=""攪料""), 1))"),"") | AJ4: =IFERROR(__xludf.DUMMYFUNCTION("IFERROR(INDEX(FILTER('製造效能'!V:V, '製造效能'!$A:$A=$C4, '製造效能'!$D:$D=$M4, '製造效能'!$E:$E=""攪料""), 1), INDEX(FILTER('製造效能'!V:V, '製造效能'!$B:$B=$D4, '製造效能'!$D:$D=$M4, '製造效能'!$E:$E=""攪料""), 1))"),"") | AK4: =COUNTIF(充填效能!$A:$A, $C4) -> 2 | AL4: =IFERROR(__xludf.DUMMYFUNCTION("IFERROR(INDEX(FILTER('充填效能'!$Q$2:$Q$1088, '充填效能'!$A$2:$A$1088=$C4, '充填效能'!$D$2:$D$1088=""排瓶""), 1), 0)"),"460") -> 460 | AM4: =IFERROR(__xludf.DUMMYFUNCTION("IFERROR(INDEX(FILTER('充填效能'!$R$2:$R$1088, '充填效能'!$A$2:$A$1088=$C4, '充填效能'!$D$2:$D$1088=""排瓶""), 1), 0)"),1) -> 1 | AN4: =IF(AL4=0, 0, $F4/AL4) -> 21.73913 | AO4: =IFERROR(__xludf.DUMMYFUNCTION("IFERROR(INDEX(FILTER('充填效能'!$Q$2:$Q$1088, '充填效能'!$A$2:$A$1088=$C4, '充填效能'!$D$2:$D$1088=""充填""), 1), 0)"),"470") -> 470 | AP4: =IFERROR(__xludf.DUMMYFUNCTION("IFERROR(INDEX(FILTER('充填效能'!$R$2:$R$1088, '充填效能'!$A$2:$A$1088=$C4, '充填效能'!$D$2:$D$1088=""充填""), 1), 0)"),3) -> 3 | AQ4: =IF(AO4=0, 0, $F4/AO4) -> 21.276596 | AR4: =AP4*AQ4 -> 63.829787
A5: 2201-22111500001-0002 | B5: =DATE(2000 + MID(A5, 6, 2), MID(A5, 8, 2), MID(A5, 10, 2)) -> 44880 | C5: MEU21C1D2P | D5: =MID(C5, 2, 6) -> EU21C1 | E5: 杜鵑花酸亮白化妝水15ML | F5: 10184 | G5: 44998 | H5: 44991 | I5: 44915 | J5: 44960 | K5: 雙層劑型 | L5: =IFERROR(__xludf.DUMMYFUNCTION("TEXTJOIN("", "", TRUE, UNIQUE(FILTER('製造效能'!$D$2:$D$1732, '製造效能'!$B$2:$B$1732 = D5)))"),"大, 小乳") -> 大, 小乳 | M5: =IFERROR(__xludf.DUMMYFUNCTION("INDEX(UNIQUE(FILTER('製造效能'!$D$2:$D$1732, ('製造效能'!$B$2:$B$1732 = D5) * ('製造效能'!$J$2:$J$1732 = MAXIFS('製造效能'!$J$2:$J$1732, '製造效能'!$B$2:$B$1732, D5)))), 1) "),"大") -> 大 | N5: =IFERROR(__xludf.DUMMYFUNCTION("TEXTJOIN("", "", TRUE, UNIQUE(FILTER('製造效能'!$K$2:$K$1732, '製造效能'!$B$2:$B$1732 = D5)))"),"水項, 乳項") -> 水項, 乳項 | O5: 11.7 | P5: =IFERROR(__xludf.DUMMYFUNCTION("IFERROR(INDEX(FILTER('充填效能'!J$2:J$1088, '充填效能'!$A$2:$A$1088=$C5, '充填效能'!$D$2:$D$1088=""充填""), 1), 0)"),"") | Q5: =IFERROR(__xludf.DUMMYFUNCTION("IFERROR(INDEX(FILTER('充填效能'!K$2:K$1088, '充填效能'!$A$2:$A$1088=$C5, '充填效能'!$D$2:$D$1088=""充填""), 1), 0)"),"") | R5: =IFERROR(__xludf.DUMMYFUNCTION("IFERROR(INDEX(FILTER('充填效能'!L$2:L$1088, '充填效能'!$A$2:$A$1088=$C5, '充填效能'!$D$2:$D$1088=""充填""), 1), 0)"),2.8) -> 2.8 | S5: =COUNTIFS(製造效能!B:B, $D5,製造效能!D:D,M5) -> 6 | T5: =IFERROR(__xludf.DUMMYFUNCTION("VALUE(REGEXEXTRACT(TO_TEXT(O5), ""\d*\.?\d+""))"),11.7) -> 11.7 | U5: =F5*T5*1.015 -> 120940.09 | V5: =IFERROR(__xludf.DUMMYFUNCTION("IFERROR(INDEX(FILTER('製造效能'!J:J, '製造效能'!A:A=$C5, '製造效能'!D:D=M5, '製造效能'!E:E=""攪料""), 1), INDEX(FILTER('製造效能'!J:J, '製造效能'!B:B=$D5, '製造效能'!D:D=M5, '製造效能'!E:E=""攪料""), 1))"),400) -> 400 | W5: =IFERROR(__xludf.DUMMYFUNCTION("IFERROR(INDEX(FILTER('製造效能'!G:G, '製造效能'!A:A=$C5, '製造效能'!D:D=M5, '製造效能'!E:E=""攪料""), 1), INDEX(FILTER('製造效能'!G:G, '製造效能'!B:B=$D5, '製造效能'!D:D=M5, '製造效能'!E:E=""攪料""), 1))"),70) -> 70 | X5: =ROUNDUP(U5/1000/V5,0) -> 1 | Y5: =W5*X5 -> 70 | Z5: =IFERROR(__xludf.DUMMYFUNCTION("IFERROR(IFERROR(INDEX(FILTER('製造效能'!G:G, '製造效能'!A:A=$C5, '製造效能'!D:D=M5, '製造效能'!E:E=""預攪""), 1), INDEX(FILTER('製造效能'!G:G, '製造效能'!B:B=$D5, '製造效能'!D:D=M5, '製造效能'!E:E=""預攪""), 1)), 0)"),70) -> 70 | AA5: =IFERROR(__xludf.DUMMYFUNCTION("IFERROR(INDEX(FILTER('製造效能'!G:G, '製造效能'!A:A=$C5, '製造效能'!D:D=M5, '製造效能'!E:E=""清洗""), 1), INDEX(FILTER('製造效能'!G:G, '製造效能'!B:B=$D5, '製造效能'!D:D=M5, '製造效能'!E:E=""清洗""), 1))"),30) -> 30 | AB5: =IFERROR(__xludf.DUMMYFUNCTION("IFERROR(INDEX(FILTER('製造效能'!N:N, '製造效能'!$A:$A=$C5, '製造效能'!$D:$D=$M5, '製造效能'!$E:$E=""攪料""), 1), INDEX(FILTER('製造效能'!N:N, '製造效能'!$B:$B=$D5, '製造效能'!$D:$D=$M5, '製造效能'!$E:$E=""攪料""), 1))"),"") | AC5: =IFERROR(__xludf.DUMMYFUNCTION("IFERROR(INDEX(FILTER('製造效能'!O:O, '製造效能'!$A:$A=$C5, '製造效能'!$D:$D=$M5, '製造效能'!$E:$E=""攪料""), 1), INDEX(FILTER('製造效能'!O:O, '製造效能'!$B:$B=$D5, '製造效能'!$D:$D=$M5, '製造效能'!$E:$E=""攪料""), 1))"),"") | AD5: =IFERROR(__xludf.DUMMYFUNCTION("IFERROR(INDEX(FILTER('製造效能'!P:P, '製造效能'!$A:$A=$C5, '製造效能'!$D:$D=$M5, '製造效能'!$E:$E=""攪料""), 1), INDEX(FILTER('製造效能'!P:P, '製造效能'!$B:$B=$D5, '製造效能'!$D:$D=$M5, '製造效能'!$E:$E=""攪料""), 1))"),"") | AE5: =IFERROR(__xludf.DUMMYFUNCTION("IFERROR(INDEX(FILTER('製造效能'!Q:Q, '製造效能'!$A:$A=$C5, '製造效能'!$D:$D=$M5, '製造效能'!$E:$E=""攪料""), 1), INDEX(FILTER('製造效能'!Q:Q, '製造效能'!$B:$B=$D5, '製造效能'!$D:$D=$M5, '製造效能'!$E:$E=""攪料""), 1))"),"") | AF5: =IFERROR(__xludf.DUMMYFUNCTION("IFERROR(INDEX(FILTER('製造效能'!R:R, '製造效能'!$A:$A=$C5, '製造效能'!$D:$D=$M5, '製造效能'!$E:$E=""攪料""), 1), INDEX(FILTER('製造效能'!R:R, '製造效能'!$B:$B=$D5, '製造效能'!$D:$D=$M5, '製造效能'!$E:$E=""攪料""), 1))"),"") | AG5: =IFERROR(__xludf.DUMMYFUNCTION("IFERROR(INDEX(FILTER('製造效能'!S:S, '製造效能'!$A:$A=$C5, '製造效能'!$D:$D=$M5, '製造效能'!$E:$E=""攪料""), 1), INDEX(FILTER('製造效能'!S:S, '製造效能'!$B:$B=$D5, '製造效能'!$D:$D=$M5, '製造效能'!$E:$E=""攪料""), 1))"),1) -> 1 | AH5: =IFERROR(__xludf.DUMMYFUNCTION("IFERROR(INDEX(FILTER('製造效能'!T:T, '製造效能'!$A:$A=$C5, '製造效能'!$D:$D=$M5, '製造效能'!$E:$E=""攪料""), 1), INDEX(FILTER('製造效能'!T:T, '製造效能'!$B:$B=$D5, '製造效能'!$D:$D=$M5, '製造效能'!$E:$E=""攪料""), 1))"),"") | AI5: =IFERROR(__xludf.DUMMYFUNCTION("IFERROR(INDEX(FILTER('製造效能'!U:U, '製造效能'!$A:$A=$C5, '製造效能'!$D:$D=$M5, '製造效能'!$E:$E=""攪料""), 1), INDEX(FILTER('製造效能'!U:U, '製造效能'!$B:$B=$D5, '製造效能'!$D:$D=$M5, '製造效能'!$E:$E=""攪料""), 1))"),"") | AJ5: =IFERROR(__xludf.DUMMYFUNCTION("IFERROR(INDEX(FILTER('製造效能'!V:V, '製造效能'!$A:$A=$C5, '製造效能'!$D:$D=$M5, '製造效能'!$E:$E=""攪料""), 1), INDEX(FILTER('製造效能'!V:V, '製造效能'!$B:$B=$D5, '製造效能'!$D:$D=$M5, '製造效能'!$E:$E=""攪料""), 1))"),"") | AK5: =COUNTIF(充填效能!$A:$A, $C5) -> 2 | AL5: =IFERROR(__xludf.DUMMYFUNCTION("IFERROR(INDEX(FILTER('充填效能'!$Q$2:$Q$1088, '充填效能'!$A$2:$A$1088=$C5, '充填效能'!$D$2:$D$1088=""排瓶""), 1), 0)"),"1100") -> 1100 | AM5: =IFERROR(__xludf.DUMMYFUNCTION("IFERROR(INDEX(FILTER('充填效能'!$R$2:$R$1088, '充填效能'!$A$2:$A$1088=$C5, '充填效能'!$D$2:$D$1088=""排瓶""), 1), 0)"),1) -> 1 | AN5: =IF(AL5=0, 0, $F5/AL5) -> 9.2581818 | AO5: =IFERROR(__xludf.DUMMYFUNCTION("IFERROR(INDEX(FILTER('充填效能'!$Q$2:$Q$1088, '充填效能'!$A$2:$A$1088=$C5, '充填效能'!$D$2:$D$1088=""充填""), 1), 0)"),"820") -> 820 | AP5: =IFERROR(__xludf.DUMMYFUNCTION("IFERROR(INDEX(FILTER('充填效能'!$R$2:$R$1088, '充填效能'!$A$2:$A$1088=$C5, '充填效能'!$D$2:$D$1088=""充填""), 1), 0)"),4) -> 4 | AQ5: =IF(AO5=0, 0, $F5/AO5) -> 12.419512 | AR5: =AP5*AQ5 -> 49.678049
A6: 2201-23021500002-0001 | B6: =DATE(2000 + MID(A6, 6, 2), MID(A6, 8, 2), MID(A6, 10, 2)) -> 44972 | C6: PN1HAE2H2P | D6: =MID(C6, 2, 6) -> N1HAE2 | E6: 玻尿酸保濕滲透乳液50ml | F6: 10000 | G6: 45107 | H6: 45007 | I6: 44978 | J6: 44981 | L6: =IFERROR(__xludf.DUMMYFUNCTION("TEXTJOIN("", "", TRUE, UNIQUE(FILTER('製造效能'!$D$2:$D$1732, '製造效能'!$B$2:$B$1732 = D6)))"),"大乳, 小乳") -> 大乳, 小乳 | M6: =IFERROR(__xludf.DUMMYFUNCTION("INDEX(UNIQUE(FILTER('製造效能'!$D$2:$D$1732, ('製造效能'!$B$2:$B$1732 = D6) * ('製造效能'!$J$2:$J$1732 = MAXIFS('製造效能'!$J$2:$J$1732, '製造效能'!$B$2:$B$1732, D6)))), 1) "),"大乳") -> 大乳 | N6: =IFERROR(__xludf.DUMMYFUNCTION("TEXTJOIN("", "", TRUE, UNIQUE(FILTER('製造效能'!$K$2:$K$1732, '製造效能'!$B$2:$B$1732 = D6)))"),"乳項") -> 乳項 | P6: =IFERROR(__xludf.DUMMYFUNCTION("IFERROR(INDEX(FILTER('充填效能'!J$2:J$1088, '充填效能'!$A$2:$A$1088=$C6, '充填效能'!$D$2:$D$1088=""充填""), 1), 0)"),"") | Q6: =IFERROR(__xludf.DUMMYFUNCTION("IFERROR(INDEX(FILTER('充填效能'!K$2:K$1088, '充填效能'!$A$2:$A$1088=$C6, '充填效能'!$D$2:$D$1088=""充填""), 1), 0)"),"") | R6: =IFERROR(__xludf.DUMMYFUNCTION("IFERROR(INDEX(FILTER('充填效能'!I$2:I$1088, '充填效能'!$A$2:$A$1088=$C6, '充填效能'!$D$2:$D$1088=""充填""), 1), 0)"),50) -> 50 | S6: =COUNTIFS(製造效能!B:B, $D6,製造效能!D:D,M6) -> 3 | T6: =IFERROR(__xludf.DUMMYFUNCTION("VALUE(REGEXEXTRACT(TO_TEXT(R6), ""\d*\.?\d+""))"),50) -> 50 | U6: =F6*T6*1.015 -> 507500 | V6: =IFERROR(__xludf.DUMMYFUNCTION("IFERROR(INDEX(FILTER('製造效能'!J:J, '製造效能'!A:A=$C6, '製造效能'!D:D=M6, '製造效能'!E:E=""攪料""), 1), INDEX(FILTER('製造效能'!J:J, '製造效能'!B:B=$D6, '製造效能'!D:D=M6, '製造效能'!E:E=""攪料""), 1))"),103) -> 103 | W6: =IFERROR(__xludf.DUMMYFUNCTION("IFERROR(INDEX(FILTER('製造效能'!G:G, '製造效能'!A:A=$C6, '製造效能'!D:D=M6, '製造效能'!E:E=""攪料""), 1), INDEX(FILTER('製造效能'!G:G, '製造效能'!B:B=$D6, '製造效能'!D:D=M6, '製造效能'!E:E=""攪料""), 1))"),180) -> 180 | X6: =ROUNDUP(U6/1000/V6,0) -> 5 | Y6: =W6*X6 -> 900 | Z6: =IFERROR(__xludf.DUMMYFUNCTION("IFERROR(IFERROR(INDEX(FILTER('製造效能'!G:G, '製造效能'!A:A=$C6, '製造效能'!D:D=M6, '製造效能'!E:E=""預攪""), 1), INDEX(FILTER('製造效能'!G:G, '製造效能'!B:B=$D6, '製造效能'!D:D=M6, '製造效能'!E:E=""預攪""), 1)), 0)"),25) -> 25 | AA6: =IFERROR(__xludf.DUMMYFUNCTION("IFERROR(INDEX(FILTER('製造效能'!G:G, '製造效能'!A:A=$C6, '製造效能'!D:D=M6, '製造效能'!E:E=""清洗""), 1), INDEX(FILTER('製造效能'!G:G, '製造效能'!B:B=$D6, '製造效能'!D:D=M6, '製造效能'!E:E=""清洗""), 1))"),40) -> 40 | AB6: =IFERROR(__xludf.DUMMYFUNCTION("IFERROR(INDEX(FILTER('製造效能'!N:N, '製造效能'!$A:$A=$C6, '製造效能'!$D:$D=$M6, '製造效能'!$E:$E=""攪料""), 1), INDEX(FILTER('製造效能'!N:N, '製造效能'!$B:$B=$D6, '製造效能'!$D:$D=$M6, '製造效能'!$E:$E=""攪料""), 1))"),"") | AC6: =IFERROR(__xludf.DUMMYFUNCTION("IFERROR(INDEX(FILTER('製造效能'!O:O, '製造效能'!$A:$A=$C6, '製造效能'!$D:$D=$M6, '製造效能'!$E:$E=""攪料""), 1), INDEX(FILTER('製造效能'!O:O, '製造效能'!$B:$B=$D6, '製造效能'!$D:$D=$M6, '製造效能'!$E:$E=""攪料""), 1))"),"") | AD6: =IFERROR(__xludf.DUMMYFUNCTION("IFERROR(INDEX(FILTER('製造效能'!P:P, '製造效能'!$A:$A=$C6, '製造效能'!$D:$D=$M6, '製造效能'!$E:$E=""攪料""), 1), INDEX(FILTER('製造效能'!P:P, '製造效能'!$B:$B=$D6, '製造效能'!$D:$D=$M6, '製造效能'!$E:$E=""攪料""), 1))"),"") | AE6: =IFERROR(__xludf.DUMMYFUNCTION("IFERROR(INDEX(FILTER('製造效能'!Q:Q, '製造效能'!$A:$A=$C6, '製造效能'!$D:$D=$M6, '製造效能'!$E:$E=""攪料""), 1), INDEX(FILTER('製造效能'!Q:Q, '製造效能'!$B:$B=$D6, '製造效能'!$D:$D=$M6, '製造效能'!$E:$E=""攪料""), 1))"),1) -> 1 | AF6: =IFERROR(__xludf.DUMMYFUNCTION("IFERROR(INDEX(FILTER('製造效能'!R:R, '製造效能'!$A:$A=$C6, '製造效能'!$D:$D=$M6, '製造效能'!$E:$E=""攪料""), 1), INDEX(FILTER('製造效能'!R:R, '製造效能'!$B:$B=$D6, '製造效能'!$D:$D=$M6, '製造效能'!$E:$E=""攪料""), 1))"),"") | AG6: =IFERROR(__xludf.DUMMYFUNCTION("IFERROR(INDEX(FILTER('製造效能'!S:S, '製造效能'!$A:$A=$C6, '製造效能'!$D:$D=$M6, '製造效能'!$E:$E=""攪料""), 1), INDEX(FILTER('製造效能'!S:S, '製造效能'!$B:$B=$D6, '製造效能'!$D:$D=$M6, '製造效能'!$E:$E=""攪料""), 1))"),"") | AH6: =IFERROR(__xludf.DUMMYFUNCTION("IFERROR(INDEX(FILTER('製造效能'!T:T, '製造效能'!$A:$A=$C6, '製造效能'!$D:$D=$M6, '製造效能'!$E:$E=""攪料""), 1), INDEX(FILTER('製造效能'!T:T, '製造效能'!$B:$B=$D6, '製造效能'!$D:$D=$M6, '製造效能'!$E:$E=""攪料""), 1))"),"") | AI6: =IFERROR(__xludf.DUMMYFUNCTION("IFERROR(INDEX(FILTER('製造效能'!U:U, '製造效能'!$A:$A=$C6, '製造效能'!$D:$D=$M6, '製造效能'!$E:$E=""攪料""), 1), INDEX(FILTER('製造效能'!U:U, '製造效能'!$B:$B=$D6, '製造效能'!$D:$D=$M6, '製造效能'!$E:$E=""攪料""), 1))"),"") | AJ6: =IFERROR(__xludf.DUMMYFUNCTION("IFERROR(INDEX(FILTER('製造效能'!V:V, '製造效能'!$A:$A=$C6, '製造效能'!$D:$D=$M6, '製造效能'!$E:$E=""攪料""), 1), INDEX(FILTER('製造效能'!V:V, '製造效能'!$B:$B=$D6, '製造效能'!$D:$D=$M6, '製造效能'!$E:$E=""攪料""), 1))"),"") | AK6: =COUNTIF(充填效能!$A:$A, $C6) -> 3 | AL6: =IFERROR(__xludf.DUMMYFUNCTION("IFERROR(INDEX(FILTER('充填效能'!$Q$2:$Q$1088, '充填效能'!$A$2:$A$1088=$C6, '充填效能'!$D$2:$D$1088=""排瓶""), 1), 0)"),"1600") -> 1600 | AM6: =IFERROR(__xludf.DUMMYFUNCTION("IFERROR(INDEX(FILTER('充填效能'!$R$2:$R$1088, '充填效能'!$A$2:$A$1088=$C6, '充填效能'!$D$2:$D$1088=""排瓶""), 1), 0)"),1) -> 1 | AN6: =IF(AL6=0, 0, $F6/AL6) -> 6.25 | AO6: =IFERROR(__xludf.DUMMYFUNCTION("IFERROR(INDEX(FILTER('充填效能'!$Q$2:$Q$1088, '充填效能'!$A$2:$A$1088=$C6, '充填效能'!$D$2:$D$1088=""充填""), 1), 0)"),"1000") -> 1000 | AP6: =IFERROR(__xludf.DUMMYFUNCTION("IFERROR(INDEX(FILTER('充填效能'!$R$2:$R$1088, '充填效能'!$A$2:$A$1088=$C6, '充填效能'!$D$2:$D$1088=""充填""), 1), 0)"),4) -> 4 | AQ6: =IF(AO6=0, 0, $F6/AO6) -> 10 | AR6: =AP6*AQ6 -> 40
A7: 2201-23030900001-0002 | B7: =DATE(2000 + MID(A7, 6, 2), MID(A7, 8, 2), MID(A7, 10, 2)) -> 44994 | C7: MBY23F1F1P | D7: =MID(C7, 2, 6) -> BY23F1 | E7: PUR%CENT 2%水楊酸淨瑕抗痘精華30ml | F7: 3000 | G7: 45071 | H7: 45012 | I7: 44994 | J7: 44977 | L7: =IFERROR(__xludf.DUMMYFUNCTION("TEXTJOIN("", "", TRUE, UNIQUE(FILTER('製造效能'!$D$2:$D$1732, '製造效能'!$B$2:$B$1732 = D7)))"),"精") -> 精 | M7: =IFERROR(__xludf.DUMMYFUNCTION("INDEX(UNIQUE(FILTER('製造效能'!$D$2:$D$1732, ('製造效能'!$B$2:$B$1732 = D7) * ('製造效能'!$J$2:$J$1732 = MAXIFS('製造效能'!$J$2:$J$1732, '製造效能'!$B$2:$B$1732, D7)))), 1) "),"精") -> 精 | N7: =IFERROR(__xludf.DUMMYFUNCTION("TEXTJOIN("", "", TRUE, UNIQUE(FILTER('製造效能'!$K$2:$K$1732, '製造效能'!$B$2:$B$1732 = D7)))"),"水項") -> 水項 | O7: =IFERROR(__xludf.DUMMYFUNCTION("IFERROR(INDEX(FILTER('充填效能'!I$2:I$1088, '充填效能'!$A$2:$A$1088=$C7, '充填效能'!$D$2:$D$1088=""充填""), 1), 0)"),30.9) -> 30.9 | P7: =IFERROR(__xludf.DUMMYFUNCTION("IFERROR(INDEX(FILTER('充填效能'!J$2:J$1088, '充填效能'!$A$2:$A$1088=$C7, '充填效能'!$D$2:$D$1088=""充填""), 1), 0)"),"") | Q7: =IFERROR(__xludf.DUMMYFUNCTION("IFERROR(INDEX(FILTER('充填效能'!K$2:K$1088, '充填效能'!$A$2:$A$1088=$C7, '充填效能'!$D$2:$D$1088=""充填""), 1), 0)"),"") | R7: =IFERROR(__xludf.DUMMYFUNCTION("IFERROR(INDEX(FILTER('充填效能'!L$2:L$1088, '充填效能'!$A$2:$A$1088=$C7, '充填效能'!$D$2:$D$1088=""充填""), 1), 0)"),"") | S7: =COUNTIFS(製造效能!B:B, $D7,製造效能!D:D,M7) -> 3 | T7: =IFERROR(__xludf.DUMMYFUNCTION("VALUE(REGEXEXTRACT(TO_TEXT(O7), ""\d*\.?\d+""))"),30.9) -> 30.9 | U7: =F7*T7*1.015 -> 94090.5 | V7: =IFERROR(__xludf.DUMMYFUNCTION("IFERROR(INDEX(FILTER('製造效能'!J:J, '製造效能'!A:A=$C7, '製造效能'!D:D=M7, '製造效能'!E:E=""攪料""), 1), INDEX(FILTER('製造效能'!J:J, '製造效能'!B:B=$D7, '製造效能'!D:D=M7, '製造效能'!E:E=""攪料""), 1))"),96) -> 96 | W7: =IFERROR(__xludf.DUMMYFUNCTION("IFERROR(INDEX(FILTER('製造效能'!G:G, '製造效能'!A:A=$C7, '製造效能'!D:D=M7, '製造效能'!E:E=""攪料""), 1), INDEX(FILTER('製造效能'!G:G, '製造效能'!B:B=$D7, '製造效能'!D:D=M7, '製造效能'!E:E=""攪料""), 1))"),55) -> 55 | X7: =ROUNDUP(U7/1000/V7,0) -> 1 | Y7: =W7*X7 -> 55 | Z7: =IFERROR(__xludf.DUMMYFUNCTION("IFERROR(IFERROR(INDEX(FILTER('製造效能'!G:G, '製造效能'!A:A=$C7, '製造效能'!D:D=M7, '製造效能'!E:E=""預攪""), 1), INDEX(FILTER('製造效能'!G:G, '製造效能'!B:B=$D7, '製造效能'!D:D=M7, '製造效能'!E:E=""預攪""), 1)), 0)"),50) -> 50 | AA7: =IFERROR(__xludf.DUMMYFUNCTION("IFERROR(INDEX(FILTER('製造效能'!G:G, '製造效能'!A:A=$C7, '製造效能'!D:D=M7, '製造效能'!E:E=""清洗""), 1), INDEX(FILTER('製造效能'!G:G, '製造效能'!B:B=$D7, '製造效能'!D:D=M7, '製造效能'!E:E=""清洗""), 1))"),15) -> 15 | AB7: =IFERROR(__xludf.DUMMYFUNCTION("IFERROR(INDEX(FILTER('製造效能'!N:N, '製造效能'!$A:$A=$C7, '製造效能'!$D:$D=$M7, '製造效能'!$E:$E=""攪料""), 1), INDEX(FILTER('製造效能'!N:N, '製造效能'!$B:$B=$D7, '製造效能'!$D:$D=$M7, '製造效能'!$E:$E=""攪料""), 1))"),"") | AC7: =IFERROR(__xludf.DUMMYFUNCTION("IFERROR(INDEX(FILTER('製造效能'!O:O, '製造效能'!$A:$A=$C7, '製造效能'!$D:$D=$M7, '製造效能'!$E:$E=""攪料""), 1), INDEX(FILTER('製造效能'!O:O, '製造效能'!$B:$B=$D7, '製造效能'!$D:$D=$M7, '製造效能'!$E:$E=""攪料""), 1))"),1) -> 1 | AD7: =IFERROR(__xludf.DUMMYFUNCTION("IFERROR(INDEX(FILTER('製造效能'!P:P, '製造效能'!$A:$A=$C7, '製造效能'!$D:$D=$M7, '製造效能'!$E:$E=""攪料""), 1), INDEX(FILTER('製造效能'!P:P, '製造效能'!$B:$B=$D7, '製造效能'!$D:$D=$M7, '製造效能'!$E:$E=""攪料""), 1))"),"") | AE7: =IFERROR(__xludf.DUMMYFUNCTION("IFERROR(INDEX(FILTER('製造效能'!Q:Q, '製造效能'!$A:$A=$C7, '製造效能'!$D:$D=$M7, '製造效能'!$E:$E=""攪料""), 1), INDEX(FILTER('製造效能'!Q:Q, '製造效能'!$B:$B=$D7, '製造效能'!$D:$D=$M7, '製造效能'!$E:$E=""攪料""), 1))"),"") | AF7: =IFERROR(__xludf.DUMMYFUNCTION("IFERROR(INDEX(FILTER('製造效能'!R:R, '製造效能'!$A:$A=$C7, '製造效能'!$D:$D=$M7, '製造效能'!$E:$E=""攪料""), 1), INDEX(FILTER('製造效能'!R:R, '製造效能'!$B:$B=$D7, '製造效能'!$D:$D=$M7, '製造效能'!$E:$E=""攪料""), 1))"),"") | AG7: =IFERROR(__xludf.DUMMYFUNCTION("IFERROR(INDEX(FILTER('製造效能'!S:S, '製造效能'!$A:$A=$C7, '製造效能'!$D:$D=$M7, '製造效能'!$E:$E=""攪料""), 1), INDEX(FILTER('製造效能'!S:S, '製造效能'!$B:$B=$D7, '製造效能'!$D:$D=$M7, '製造效能'!$E:$E=""攪料""), 1))"),"") | AH7: =IFERROR(__xludf.DUMMYFUNCTION("IFERROR(INDEX(FILTER('製造效能'!T:T, '製造效能'!$A:$A=$C7, '製造效能'!$D:$D=$M7, '製造效能'!$E:$E=""攪料""), 1), INDEX(FILTER('製造效能'!T:T, '製造效能'!$B:$B=$D7, '製造效能'!$D:$D=$M7, '製造效能'!$E:$E=""攪料""), 1))"),"") | AI7: =IFERROR(__xludf.DUMMYFUNCTION("IFERROR(INDEX(FILTER('製造效能'!U:U, '製造效能'!$A:$A=$C7, '製造效能'!$D:$D=$M7, '製造效能'!$E:$E=""攪料""), 1), INDEX(FILTER('製造效能'!U:U, '製造效能'!$B:$B=$D7, '製造效能'!$D:$D=$M7, '製造效能'!$E:$E=""攪料""), 1))"),"") | AJ7: =IFERROR(__xludf.DUMMYFUNCTION("IFERROR(INDEX(FILTER('製造效能'!V:V, '製造效能'!$A:$A=$C7, '製造效能'!$D:$D=$M7, '製造效能'!$E:$E=""攪料""), 1), INDEX(FILTER('製造效能'!V:V, '製造效能'!$B:$B=$D7, '製造效能'!$D:$D=$M7, '製造效能'!$E:$E=""攪料""), 1))"),"") | AK7: =COUNTIF(充填效能!$A:$A, $C7) -> 2 | AL7: =IFERROR(__xludf.DUMMYFUNCTION("IFERROR(INDEX(FILTER('充填效能'!$Q$2:$Q$1088, '充填效能'!$A$2:$A$1088=$C7, '充填效能'!$D$2:$D$1088=""排瓶""), 1), 0)"),"1500") -> 1500 | AM7: =IFERROR(__xludf.DUMMYFUNCTION("IFERROR(INDEX(FILTER('充填效能'!$R$2:$R$1088, '充填效能'!$A$2:$A$1088=$C7, '充填效能'!$D$2:$D$1088=""排瓶""), 1), 0)"),1) -> 1 | AN7: =IF(AL7=0, 0, $F7/AL7) -> 2 | AO7: =IFERROR(__xludf.DUMMYFUNCTION("IFERROR(INDEX(FILTER('充填效能'!$Q$2:$Q$1088, '充填效能'!$A$2:$A$1088=$C7, '充填效能'!$D$2:$D$1088=""充填""), 1), 0)"),"1200") -> 1200 | AP7: =IFERROR(__xludf.DUMMYFUNCTION("IFERROR(INDEX(FILTER('充填效能'!$R$2:$R$1088, '充填效能'!$A$2:$A$1088=$C7, '充填效能'!$D$2:$D$1088=""充填""), 1), 0)"),4) -> 4 | AQ7: =IF(AO7=0, 0, $F7/AO7) -> 2.5 | AR7: =AP7*AQ7 -> 10
A8: 2201-23031600003-0001 | B8: =DATE(2000 + MID(A8, 6, 2), MID(A8, 8, 2), MID(A8, 10, 2)) -> 45001 | C8: PN1UVH7H2P | D8: =MID(C8, 2, 6) -> N1UVH7 | E8: 水感全效防曬乳 SPF50+/★★★★ | F8: 20000 | G8: 45107 | H8: 45023 | I8: 44987 | J8: 44986 | L8: =IFERROR(__xludf.DUMMYFUNCTION("TEXTJOIN("", "", TRUE, UNIQUE(FILTER('製造效能'!$D$2:$D$1732, '製造效能'!$B$2:$B$1732 = D8)))"),"精") -> 精 | M8: =IFERROR(__xludf.DUMMYFUNCTION("INDEX(UNIQUE(FILTER('製造效能'!$D$2:$D$1732, ('製造效能'!$B$2:$B$1732 = D8) * ('製造效能'!$J$2:$J$1732 = MAXIFS('製造效能'!$J$2:$J$1732, '製造效能'!$B$2:$B$1732, D8)))), 1) "),"精") -> 精 | N8: =IFERROR(__xludf.DUMMYFUNCTION("TEXTJOIN("", "", TRUE, UNIQUE(FILTER('製造效能'!$K$2:$K$1732, '製造效能'!$B$2:$B$1732 = D8)))"),"乳項") -> 乳項 | P8: =IFERROR(__xludf.DUMMYFUNCTION("IFERROR(INDEX(FILTER('充填效能'!J$2:J$1088, '充填效能'!$A$2:$A$1088=$C8, '充填效能'!$D$2:$D$1088=""充填""), 1), 0)"),"") | Q8: =IFERROR(__xludf.DUMMYFUNCTION("IFERROR(INDEX(FILTER('充填效能'!K$2:K$1088, '充填效能'!$A$2:$A$1088=$C8, '充填效能'!$D$2:$D$1088=""充填""), 1), 0)"),"") | R8: =IFERROR(__xludf.DUMMYFUNCTION("IFERROR(INDEX(FILTER('充填效能'!I$2:I$1088, '充填效能'!$A$2:$A$1088=$C8, '充填效能'!$D$2:$D$1088=""充填""), 1), 0)"),50) -> 50 | S8: =COUNTIFS(製造效能!B:B, $D8,製造效能!D:D,M8) -> 3 | T8: =IFERROR(__xludf.DUMMYFUNCTION("VALUE(REGEXEXTRACT(TO_TEXT(R8), ""\d*\.?\d+""))"),50) -> 50 | U8: =F8*T8*1.015 -> 1015000 | V8: =IFERROR(__xludf.DUMMYFUNCTION("IFERROR(INDEX(FILTER('製造效能'!J:J, '製造效能'!A:A=$C8, '製造效能'!D:D=M8, '製造效能'!E:E=""攪料""), 1), INDEX(FILTER('製造效能'!J:J, '製造效能'!B:B=$D8, '製造效能'!D:D=M8, '製造效能'!E:E=""攪料""), 1))"),70) -> 70 | W8: =IFERROR(__xludf.DUMMYFUNCTION("IFERROR(INDEX(FILTER('製造效能'!G:G, '製造效能'!A:A=$C8, '製造效能'!D:D=M8, '製造效能'!E:E=""攪料""), 1), INDEX(FILTER('製造效能'!G:G, '製造效能'!B:B=$D8, '製造效能'!D:D=M8, '製造效能'!E:E=""攪料""), 1))"),125) -> 125 | X8: =ROUNDUP(U8/1000/V8,0) -> 15 | Y8: =W8*X8 -> 1875 | Z8: =IFERROR(__xludf.DUMMYFUNCTION("IFERROR(IFERROR(INDEX(FILTER('製造效能'!G:G, '製造效能'!A:A=$C8, '製造效能'!D:D=M8, '製造效能'!E:E=""預攪""), 1), INDEX(FILTER('製造效能'!G:G, '製造效能'!B:B=$D8, '製造效能'!D:D=M8, '製造效能'!E:E=""預攪""), 1)), 0)"),35) -> 35 | AA8: =IFERROR(__xludf.DUMMYFUNCTION("IFERROR(INDEX(FILTER('製造效能'!G:G, '製造效能'!A:A=$C8, '製造效能'!D:D=M8, '製造效能'!E:E=""清洗""), 1), INDEX(FILTER('製造效能'!G:G, '製造效能'!B:B=$D8, '製造效能'!D:D=M8, '製造效能'!E:E=""清洗""), 1))"),15) -> 15 | AB8: =IFERROR(__xludf.DUMMYFUNCTION("IFERROR(INDEX(FILTER('製造效能'!N:N, '製造效能'!$A:$A=$C8, '製造效能'!$D:$D=$M8, '製造效能'!$E:$E=""攪料""), 1), INDEX(FILTER('製造效能'!N:N, '製造效能'!$B:$B=$D8, '製造效能'!$D:$D=$M8, '製造效能'!$E:$E=""攪料""), 1))"),"") | AC8: =IFERROR(__xludf.DUMMYFUNCTION("IFERROR(INDEX(FILTER('製造效能'!O:O, '製造效能'!$A:$A=$C8, '製造效能'!$D:$D=$M8, '製造效能'!$E:$E=""攪料""), 1), INDEX(FILTER('製造效能'!O:O, '製造效能'!$B:$B=$D8, '製造效能'!$D:$D=$M8, '製造效能'!$E:$E=""攪料""), 1))"),1) -> 1 | AD8: =IFERROR(__xludf.DUMMYFUNCTION("IFERROR(INDEX(FILTER('製造效能'!P:P, '製造效能'!$A:$A=$C8, '製造效能'!$D:$D=$M8, '製造效能'!$E:$E=""攪料""), 1), INDEX(FILTER('製造效能'!P:P, '製造效能'!$B:$B=$D8, '製造效能'!$D:$D=$M8, '製造效能'!$E:$E=""攪料""), 1))"),"") | AE8: =IFERROR(__xludf.DUMMYFUNCTION("IFERROR(INDEX(FILTER('製造效能'!Q:Q, '製造效能'!$A:$A=$C8, '製造效能'!$D:$D=$M8, '製造效能'!$E:$E=""攪料""), 1), INDEX(FILTER('製造效能'!Q:Q, '製造效能'!$B:$B=$D8, '製造效能'!$D:$D=$M8, '製造效能'!$E:$E=""攪料""), 1))"),"") | AF8: =IFERROR(__xludf.DUMMYFUNCTION("IFERROR(INDEX(FILTER('製造效能'!R:R, '製造效能'!$A:$A=$C8, '製造效能'!$D:$D=$M8, '製造效能'!$E:$E=""攪料""), 1), INDEX(FILTER('製造效能'!R:R, '製造效能'!$B:$B=$D8, '製造效能'!$D:$D=$M8, '製造效能'!$E:$E=""攪料""), 1))"),"") | AG8: =IFERROR(__xludf.DUMMYFUNCTION("IFERROR(INDEX(FILTER('製造效能'!S:S, '製造效能'!$A:$A=$C8, '製造效能'!$D:$D=$M8, '製造效能'!$E:$E=""攪料""), 1), INDEX(FILTER('製造效能'!S:S, '製造效能'!$B:$B=$D8, '製造效能'!$D:$D=$M8, '製造效能'!$E:$E=""攪料""), 1))"),"") | AH8: =IFERROR(__xludf.DUMMYFUNCTION("IFERROR(INDEX(FILTER('製造效能'!T:T, '製造效能'!$A:$A=$C8, '製造效能'!$D:$D=$M8, '製造效能'!$E:$E=""攪料""), 1), INDEX(FILTER('製造效能'!T:T, '製造效能'!$B:$B=$D8, '製造效能'!$D:$D=$M8, '製造效能'!$E:$E=""攪料""), 1))"),"") | AI8: =IFERROR(__xludf.DUMMYFUNCTION("IFERROR(INDEX(FILTER('製造效能'!U:U, '製造效能'!$A:$A=$C8, '製造效能'!$D:$D=$M8, '製造效能'!$E:$E=""攪料""), 1), INDEX(FILTER('製造效能'!U:U, '製造效能'!$B:$B=$D8, '製造效能'!$D:$D=$M8, '製造效能'!$E:$E=""攪料""), 1))"),"") | AJ8: =IFERROR(__xludf.DUMMYFUNCTION("IFERROR(INDEX(FILTER('製造效能'!V:V, '製造效能'!$A:$A=$C8, '製造效能'!$D:$D=$M8, '製造效能'!$E:$E=""攪料""), 1), INDEX(FILTER('製造效能'!V:V, '製造效能'!$B:$B=$D8, '製造效能'!$D:$D=$M8, '製造效能'!$E:$E=""攪料""), 1))"),"") | AK8: =COUNTIF(充填效能!$A:$A, $C8) -> 1 | AL8: =IFERROR(__xludf.DUMMYFUNCTION("IFERROR(INDEX(FILTER('充填效能'!$Q$2:$Q$1088, '充填效能'!$A$2:$A$1088=$C8, '充填效能'!$D$2:$D$1088=""排瓶""), 1), 0)"),0) -> 0 | AM8: =IFERROR(__xludf.DUMMYFUNCTION("IFERROR(INDEX(FILTER('充填效能'!$R$2:$R$1088, '充填效能'!$A$2:$A$1088=$C8, '充填效能'!$D$2:$D$1088=""排瓶""), 1), 0)"),0) -> 0 | AN8: =IF(AL8=0, 0, $F8/AL8) -> 0 | AO8: =IFERROR(__xludf.DUMMYFUNCTION("IFERROR(INDEX(FILTER('充填效能'!$Q$2:$Q$1088, '充填效能'!$A$2:$A$1088=$C8, '充填效能'!$D$2:$D$1088=""充填""), 1), 0)"),"800") -> 800 | AP8: =IFERROR(__xludf.DUMMYFUNCTION("IFERROR(INDEX(FILTER('充填效能'!$R$2:$R$1088, '充填效能'!$A$2:$A$1088=$C8, '充填效能'!$D$2:$D$1088=""充填""), 1), 0)"),4) -> 4 | AQ8: =IF(AO8=0, 0, $F8/AO8) -> 25 | AR8: =AP8*AQ8 -> 100
A9: 2201-23020200002-0001 | B9: =DATE(2000 + MID(A9, 6, 2), MID(A9, 8, 2), MID(A9, 10, 2)) -> 44959 | C9: PN1CAE2H1P | D9: =MID(C9, 2, 6) -> N1CAE2 | E9: 積雪草B5密集護理霜50ml | F9: 3783 | G9: 45061 | H9: 45026 | I9: 44959 | J9: 44974 | L9: =IFERROR(__xludf.DUMMYFUNCTION("TEXTJOIN("", "", TRUE, UNIQUE(FILTER('製造效能'!$D$2:$D$1732, '製造效能'!$B$2:$B$1732 = D9)))"),"小乳") -> 小乳 | M9: =IFERROR(__xludf.DUMMYFUNCTION("INDEX(UNIQUE(FILTER('製造效能'!$D$2:$D$1732, ('製造效能'!$B$2:$B$1732 = D9) * ('製造效能'!$J$2:$J$1732 = MAXIFS('製造效能'!$J$2:$J$1732, '製造效能'!$B$2:$B$1732, D9)))), 1) "),"小乳") -> 小乳 | N9: =IFERROR(__xludf.DUMMYFUNCTION("TEXTJOIN("", "", TRUE, UNIQUE(FILTER('製造效能'!$K$2:$K$1732, '製造效能'!$B$2:$B$1732 = D9)))"),"乳項") -> 乳項 | P9: =IFERROR(__xludf.DUMMYFUNCTION("IFERROR(INDEX(FILTER('充填效能'!J$2:J$1088, '充填效能'!$A$2:$A$1088=$C9, '充填效能'!$D$2:$D$1088=""充填""), 1), 0)"),"") | Q9: =IFERROR(__xludf.DUMMYFUNCTION("IFERROR(INDEX(FILTER('充填效能'!K$2:K$1088, '充填效能'!$A$2:$A$1088=$C9, '充填效能'!$D$2:$D$1088=""充填""), 1), 0)"),"") | R9: =IFERROR(__xludf.DUMMYFUNCTION("IFERROR(INDEX(FILTER('充填效能'!I$2:I$1088, '充填效能'!$A$2:$A$1088=$C9, '充填效能'!$D$2:$D$1088=""充填""), 1), 0)"),42.5) -> 42.5 | S9: =COUNTIFS(製造效能!B:B, $D9,製造效能!D:D,M9) -> 3 | T9: =IFERROR(__xludf.DUMMYFUNCTION("VALUE(REGEXEXTRACT(TO_TEXT(R9), ""\d*\.?\d+""))"),42.5) -> 42.5 | U9: =F9*T9*1.015 -> 163189.16 | V9: =IFERROR(__xludf.DUMMYFUNCTION("IFERROR(INDEX(FILTER('製造效能'!J:J, '製造效能'!A:A=$C9, '製造效能'!D:D=M9, '製造效能'!E:E=""攪料""), 1), INDEX(FILTER('製造效能'!J:J, '製造效能'!B:B=$D9, '製造效能'!D:D=M9, '製造效能'!E:E=""攪料""), 1))"),52) -> 52 | W9: =IFERROR(__xludf.DUMMYFUNCTION("IFERROR(INDEX(FILTER('製造效能'!G:G, '製造效能'!A:A=$C9, '製造效能'!D:D=M9, '製造效能'!E:E=""攪料""), 1), INDEX(FILTER('製造效能'!G:G, '製造效能'!B:B=$D9, '製造效能'!D:D=M9, '製造效能'!E:E=""攪料""), 1))"),140) -> 140 | X9: =ROUNDUP(U9/1000/V9,0) -> 4 | Y9: =W9*X9 -> 560 | Z9: =IFERROR(__xludf.DUMMYFUNCTION("IFERROR(IFERROR(INDEX(FILTER('製造效能'!G:G, '製造效能'!A:A=$C9, '製造效能'!D:D=M9, '製造效能'!E:E=""預攪""), 1), INDEX(FILTER('製造效能'!G:G, '製造效能'!B:B=$D9, '製造效能'!D:D=M9, '製造效能'!E:E=""預攪""), 1)), 0)"),40) -> 40 | AA9: =IFERROR(__xludf.DUMMYFUNCTION("IFERROR(INDEX(FILTER('製造效能'!G:G, '製造效能'!A:A=$C9, '製造效能'!D:D=M9, '製造效能'!E:E=""清洗""), 1), INDEX(FILTER('製造效能'!G:G, '製造效能'!B:B=$D9, '製造效能'!D:D=M9, '製造效能'!E:E=""清洗""), 1))"),60) -> 60 | AB9: =IFERROR(__xludf.DUMMYFUNCTION("IFERROR(INDEX(FILTER('製造效能'!N:N, '製造效能'!$A:$A=$C9, '製造效能'!$D:$D=$M9, '製造效能'!$E:$E=""攪料""), 1), INDEX(FILTER('製造效能'!N:N, '製造效能'!$B:$B=$D9, '製造效能'!$D:$D=$M9, '製造效能'!$E:$E=""攪料""), 1))"),"") | AC9: =IFERROR(__xludf.DUMMYFUNCTION("IFERROR(INDEX(FILTER('製造效能'!O:O, '製造效能'!$A:$A=$C9, '製造效能'!$D:$D=$M9, '製造效能'!$E:$E=""攪料""), 1), INDEX(FILTER('製造效能'!O:O, '製造效能'!$B:$B=$D9, '製造效能'!$D:$D=$M9, '製造效能'!$E:$E=""攪料""), 1))"),"") | AD9: =IFERROR(__xludf.DUMMYFUNCTION("IFERROR(INDEX(FILTER('製造效能'!P:P, '製造效能'!$A:$A=$C9, '製造效能'!$D:$D=$M9, '製造效能'!$E:$E=""攪料""), 1), INDEX(FILTER('製造效能'!P:P, '製造效能'!$B:$B=$D9, '製造效能'!$D:$D=$M9, '製造效能'!$E:$E=""攪料""), 1))"),1) -> 1 | AE9: =IFERROR(__xludf.DUMMYFUNCTION("IFERROR(INDEX(FILTER('製造效能'!Q:Q, '製造效能'!$A:$A=$C9, '製造效能'!$D:$D=$M9, '製造效能'!$E:$E=""攪料""), 1), INDEX(FILTER('製造效能'!Q:Q, '製造效能'!$B:$B=$D9, '製造效能'!$D:$D=$M9, '製造效能'!$E:$E=""攪料""), 1))"),"") | AF9: =IFERROR(__xludf.DUMMYFUNCTION("IFERROR(INDEX(FILTER('製造效能'!R:R, '製造效能'!$A:$A=$C9, '製造效能'!$D:$D=$M9, '製造效能'!$E:$E=""攪料""), 1), INDEX(FILTER('製造效能'!R:R, '製造效能'!$B:$B=$D9, '製造效能'!$D:$D=$M9, '製造效能'!$E:$E=""攪料""), 1))"),"") | AG9: =IFERROR(__xludf.DUMMYFUNCTION("IFERROR(INDEX(FILTER('製造效能'!S:S, '製造效能'!$A:$A=$C9, '製造效能'!$D:$D=$M9, '製造效能'!$E:$E=""攪料""), 1), INDEX(FILTER('製造效能'!S:S, '製造效能'!$B:$B=$D9, '製造效能'!$D:$D=$M9, '製造效能'!$E:$E=""攪料""), 1))"),"") | AH9: =IFERROR(__xludf.DUMMYFUNCTION("IFERROR(INDEX(FILTER('製造效能'!T:T, '製造效能'!$A:$A=$C9, '製造效能'!$D:$D=$M9, '製造效能'!$E:$E=""攪料""), 1), INDEX(FILTER('製造效能'!T:T, '製造效能'!$B:$B=$D9, '製造效能'!$D:$D=$M9, '製造效能'!$E:$E=""攪料""), 1))"),"") | AI9: =IFERROR(__xludf.DUMMYFUNCTION("IFERROR(INDEX(FILTER('製造效能'!U:U, '製造效能'!$A:$A=$C9, '製造效能'!$D:$D=$M9, '製造效能'!$E:$E=""攪料""), 1), INDEX(FILTER('製造效能'!U:U, '製造效能'!$B:$B=$D9, '製造效能'!$D:$D=$M9, '製造效能'!$E:$E=""攪料""), 1))"),"") | AJ9: =IFERROR(__xludf.DUMMYFUNCTION("IFERROR(INDEX(FILTER('製造效能'!V:V, '製造效能'!$A:$A=$C9, '製造效能'!$D:$D=$M9, '製造效能'!$E:$E=""攪料""), 1), INDEX(FILTER('製造效能'!V:V, '製造效能'!$B:$B=$D9, '製造效能'!$D:$D=$M9, '製造效能'!$E:$E=""攪料""), 1))"),"") | AK9: =COUNTIF(充填效能!$A:$A, $C9) -> 1 | AL9: =IFERROR(__xludf.DUMMYFUNCTION("IFERROR(INDEX(FILTER('充填效能'!$Q$2:$Q$1088, '充填效能'!$A$2:$A$1088=$C9, '充填效能'!$D$2:$D$1088=""排瓶""), 1), 0)"),0) -> 0 | AM9: =IFERROR(__xludf.DUMMYFUNCTION("IFERROR(INDEX(FILTER('充填效能'!$R$2:$R$1088, '充填效能'!$A$2:$A$1088=$C9, '充填效能'!$D$2:$D$1088=""排瓶""), 1), 0)"),0) -> 0 | AN9: =IF(AL9=0, 0, $F9/AL9) -> 0 | AO9: =IFERROR(__xludf.DUMMYFUNCTION("IFERROR(INDEX(FILTER('充填效能'!$Q$2:$Q$1088, '充填效能'!$A$2:$A$1088=$C9, '充填效能'!$D$2:$D$1088=""充填""), 1), 0)"),420) -> 420 | AP9: =IFERROR(__xludf.DUMMYFUNCTION("IFERROR(INDEX(FILTER('充填效能'!$R$2:$R$1088, '充填效能'!$A$2:$A$1088=$C9, '充填效能'!$D$2:$D$1088=""充填""), 1), 0)"),3) -> 3 | AQ9: =IF(AO9=0, 0, $F9/AO9) -> 9.0071429 | AR9: =AP9*AQ9 -> 27.021429
